Workbook

Sheet Prisoversikt juni 2026
A1: We4you AS – Prisoversikt Sentralbord 2026 | August 2026 | Beregnet vs Faktisk (Tripletex)
A2: # | B2: Kunde | C2: Status | D2: Prismodell | E2: Pris 2026 | F2: Inkludert | G2: Merknader / pristrapp | H2: Besvarte anrop | I2: Beregnet pris | J2: Faktisk august(Tripletex ekskl.) | K2: Avvik (J−I)
A3: STANDARDTABELL 0-99 (inkl. fast pris-varianter)
A4: 1 | B4: 2Clean AS | C4: Aktiv | D4: Standardtabell 0-99 | E4: kr 2 960 / mnd | F4: 0–99 samtaler | G4: Ekstra engangsfaktura juni: kr 1 070 (e-postmigrering til Nordn) – ikke sentralbord | H4: 48 | I4: =IF(H4="–","–",IFERROR(VLOOKUP(H4,Tabeller!$A$2:$B$35,2,TRUE()),2960)) -> 2960 | J4: 2960 | K4: =IF(ISNUMBER(I4),IF(ISNUMBER(J4),J4-I4,""),"–") -> 0
A5: 2 | B5: Advokat Olga Halvorsen AS | C5: Aktiv | D5: Standardtabell 0-99 | E5: kr 2 960 / mnd | F5: 0–99 samtaler | H5: 23 | I5: =IF(H5="–","–",IFERROR(VLOOKUP(H5,Tabeller!$A$2:$B$35,2,TRUE()),2960)) -> 2960 | J5: 2960 | K5: =IF(ISNUMBER(I5),IF(ISNUMBER(J5),J5-I5,""),"–") -> 0
A6: 3 | B6: Advokat Sandra Latotinaite | C6: Aktiv | D6: Standardtabell 0-99 | E6: kr 2 960 / mnd | F6: 0–99 samtaler | H6: 22 | I6: =IF(H6="–","–",IFERROR(VLOOKUP(H6,Tabeller!$A$2:$B$35,2,TRUE()),2960)) -> 2960 | J6: 2960 | K6: =IF(ISNUMBER(I6),IF(ISNUMBER(J6),J6-I6,""),"–") -> 0
A7: 4 | B7: Akkodis – Data Respons | C7: Aktiv | D7: Standardtabell 0-99 | E7: kr 2 960 / mnd | F7: 0–99 samtaler | G7: Tidl. Datarespons | H7: 9 | I7: =IF(H7="–","–",IFERROR(VLOOKUP(H7,Tabeller!$A$2:$B$35,2,TRUE()),2960)) -> 2960 | J7: 2960 | K7: =IF(ISNUMBER(I7),IF(ISNUMBER(J7),J7-I7,""),"–") -> 0
A8: 5 | B8: Bodyfly Frogner AS | C8: Aktiv | D8: Fast pris | E8: kr 1 600 / mnd inkl. 99 anrop | F8: 0–99 anrop | G8: Fast pris 1 600 – IKKE standardtabell 2 960 | H8: 15 | I8: =1600 -> 1600 | J8: 1600 | K8: =IF(ISNUMBER(I8),IF(ISNUMBER(J8),J8-I8,""),"–") -> 0
A9: 6 | B9: Calpro AS | C9: Aktiv | D9: Standardtabell 0-99 | E9: kr 2 960 / mnd | F9: 0–99 samtaler | H9: 7 | I9: =IF(H9="–","–",IFERROR(VLOOKUP(H9,Tabeller!$A$2:$B$35,2,TRUE()),2960)) -> 2960 | J9: 2960 | K9: =IF(ISNUMBER(I9),IF(ISNUMBER(J9),J9-I9,""),"–") -> 0
A10: 7 | B10: Coromatic AS | C10: Aktiv | D10: Standardtabell 0-99 | E10: kr 2 960 / mnd | F10: 0–99 samtaler | G10: Coromatic skal følgestandard tabell 0-99 | H10: 110 | I10: 3580 | J10: 3580 | K10: =IF(ISNUMBER(I10),IF(ISNUMBER(J10),J10-I10,""),"–") -> 0
A11: 8 | B11: Dal Media (Digital Media Group AS) | C11: Aktiv | D11: Standardtabell 0-99 + faste tillegg 199x3=kr 597 | E11: Standardtabell (hoved-kø)Tell med samlet antall besvart samtaler for Dal media(Digital media group AS) + 3 selskaper på statistikken: TDC Caravan + Saltando + Victoria + + 3 × kr 199 tillegg | F11: Se anrop | G11: Fakturer samlet antall besvart samtaler for 3 selskaper på statistikken: TDC Caravan + Saltando + Victoria + (3×199kr). Tripletex-navn: Digital Media Group AS | H11: 206 | I11: =IF(H11="–","–",IFERROR(VLOOKUP(H11,Tabeller!$A$2:$B$35,2,TRUE()),2960)+3*199) -> 5267 | J11: 5267 | K11: =IF(ISNUMBER(I11),IF(ISNUMBER(J11),J11-I11,""),"–") -> 0
A12: 9 | B12: Element Logic AS | C12: Aktiv | D12: Kvartalsvis (standardtabell) | E12: kr 8 880 / kvartal | F12: Kvartalsvis forskudd | G12: April–juni betalt april – neste faktura juli | H12: 46 | I12: =0 -> 0 | J12: 0 | K12: =IF(ISNUMBER(I12),IF(ISNUMBER(J12),J12-I12,""),"–") -> 0
A13: 10 | B13: Element Logic Sweden AB | C13: Aktiv | D13: Kvartalsvis (standardtabell) | E13: kr 8 880 / kvartal | F13: Kvartalsvis forskudd | G13: Q3-forskudd betalt juni | H13: 40 | I13: =8880 -> 8880 | J13: 8880 | K13: =IF(ISNUMBER(I13),IF(ISNUMBER(J13),J13-I13,""),"–") -> 0
A14: 11 | B14: First Mover Group Norge AS / Relokator | C14: Aktiv | D14: Standardtabell 0-99 + tillegg | E14: kr 2 960 / mnd + tillegg | F14: 0–99 samtaler | H14: 117 | I14: =IF(H14="–","–",IFERROR(VLOOKUP(H14,Tabeller!$A$2:$B$35,2,TRUE()),2960)+1439) -> 5019 | J14: 5019 | K14: =IF(ISNUMBER(I14),IF(ISNUMBER(J14),J14-I14,""),"–") -> 0
A15: 12 | B15: Foma Norge AS | C15: Aktiv | D15: Standardtabell + grunnpris kr 199 | E15: Standardtabell + kr 199 grunnpris / mnd | F15: 0–99+ samtaler | H15: 309 | I15: =IF(H15="–","–",IFERROR(VLOOKUP(H15,Tabeller!$A$2:$B$35,2,TRUE()),2960)+199) -> 7029 | J15: 7029 | K15: =IF(ISNUMBER(I15),IF(ISNUMBER(J15),J15-I15,""),"–") -> 0
A16: 13 | B16: Gass og Pusteservice AS | C16: Aktiv | D16: Standardtabell + utvidet åpningstid | E16: kr 2 960 / mnd + kr 360 utvidet åpningstid | F16: 0–99 samtaler | G16: Tillegg utvidet åpningstid: kr 360/mnd | H16: 83 | I16: =IF(H16="–","–",IFERROR(VLOOKUP(H16,Tabeller!$A$2:$B$35,2,TRUE()),2960)+360) -> 3320 | J16: 3320 | K16: =IF(ISNUMBER(I16),IF(ISNUMBER(J16),J16-I16,""),"–") -> 0
A17: 14 | B17: Kardex Norge AS | C17: Aktiv | D17: Standardtabell 0-99 | E17: kr 2 960 / mnd | F17: 0–99 samtaler | H17: 65 | I17: =IF(H17="–","–",IFERROR(VLOOKUP(H17,Tabeller!$A$2:$B$35,2,TRUE()),2960)) -> 2960 | J17: 2960 | K17: =IF(ISNUMBER(I17),IF(ISNUMBER(J17),J17-I17,""),"–") -> 0
A18: 15 | B18: KTV Group AS | C18: Aktiv | D18: Standardtabell 0-99 (10 % rabatt) | E18: kr 2 664 / mnd (2 960 med 10 % rabatt) | F18: 0–99 samtaler | G18: Fast 10 % rabatt på standardtabell | H18: 15 | I18: =IF(H18="–","–",ROUND(IFERROR(VLOOKUP(H18,Tabeller!$A$2:$B$35,2,TRUE()),2960)*0.9,0)) -> 2664 | J18: 2664 | K18: =IF(ISNUMBER(I18),IF(ISNUMBER(J18),J18-I18,""),"–") -> 0
A19: 16 | B19: NOAH AS | C19: Aktiv | D19: Standardtabell 0-99 | E19: kr 2 960 / mnd | F19: 0–99 samtaler | H19: 49 | I19: =IF(H19="–","–",IFERROR(VLOOKUP(H19,Tabeller!$A$2:$B$35,2,TRUE()),2960)) -> 2960 | J19: 2960 | K19: =IF(ISNUMBER(I19),IF(ISNUMBER(J19),J19-I19,""),"–") -> 0
A20: 17 | B20: Norenco Norge AS | C20: Aktiv | D20: Standardtabell + tillegg linje | E20: Standardtabell + kr 199 tillegg | F20: 0–99 samtaler | H20: 68 | I20: =IF(H20="–","–",IFERROR(VLOOKUP(H20,Tabeller!$A$2:$B$35,2,TRUE()),2960)+199) -> 3159 | J20: 3159 | K20: =IF(ISNUMBER(I20),IF(ISNUMBER(J20),J20-I20,""),"–") -> 0
A21: 18 | B21: Senter for stress og Traumepsykologi AS | C21: Aktiv | D21: Standardtabell 0-99 | E21: kr 2 960 / mnd | F21: 0–99 samtaler | H21: 47 | I21: =IF(H21="–","–",IFERROR(VLOOKUP(H21,Tabeller!$A$2:$B$35,2,TRUE()),2960)) -> 2960 | J21: 2960 | K21: =IF(ISNUMBER(I21),IF(ISNUMBER(J21),J21-I21,""),"–") -> 0
A22: 19 | B22: Spraying Systems Sverige AB | C22: Aktiv | D22: Standardtabell 0-99 | E22: kr 2 960 / mnd | F22: 0–99 samtaler | H22: 14 | I22: =IF(H22="–","–",IFERROR(VLOOKUP(H22,Tabeller!$A$2:$B$35,2,TRUE()),2960)) -> 2960 | J22: 2960 | K22: =IF(ISNUMBER(I22),IF(ISNUMBER(J22),J22-I22,""),"–") -> 0
A23: 20 | B23: Standard Norge AS | C23: Aktiv | D23: Standardtabell 0-99 | E23: kr 2 960 / mnd | F23: 0–99 samtaler | H23: 175 | I23: =IF(H23="–","–",IFERROR(VLOOKUP(H23,Tabeller!$A$2:$B$35,2,TRUE()),2960)) -> 4090 | J23: 4090 | K23: =IF(ISNUMBER(I23),IF(ISNUMBER(J23),J23-I23,""),"–") -> 0
A24: 21 | B24: TD Synnex Norway AS | C24: Aktiv | D24: Standardtabell 0-99 | E24: kr 2 960 / mnd | F24: 0–99 samtaler | H24: 128 | I24: 3580 | J24: 3580 | K24: =IF(ISNUMBER(I24),IF(ISNUMBER(J24),J24-I24,""),"–") -> 0
A25: 22 | B25: Teva AS (Teva-Actavis) | C25: Aktiv | D25: Standardtabell + grunnpris kr 199 | E25: Standardtabell + kr 199 grunnpris | F25: 0–99 samtaler | H25: 13 | I25: 3159 | J25: 3159 | K25: =IF(ISNUMBER(I25),IF(ISNUMBER(J25),J25-I25,""),"–") -> 0
A26: 23 | B26: Ultralydklinikken AS | C26: Aktiv | D26: Standardtabell 0-99 | E26: kr 2 960 / mnd | F26: 0–99 samtaler | H26: 74 | I26: =IF(H26="–","–",IFERROR(VLOOKUP(H26,Tabeller!$A$2:$B$35,2,TRUE()),2960)) -> 2960 | J26: 2960 | K26: =IF(ISNUMBER(I26),IF(ISNUMBER(J26),J26-I26,""),"–") -> 0
A27: 24 | B27: Veidekke Industri AS – Møre | C27: Aktiv | D27: Standardtabell 0-99 | E27: kr 2 960 / mnd | F27: 0–99 samtaler | G27: Kø 3792 · Kunde nr 32722 | H27: 42 | I27: =IF(H27="–","–",IFERROR(VLOOKUP(H27,Tabeller!$A$2:$B$35,2,TRUE()),2960)) -> 2960 | J27: 2960 | K27: =IF(ISNUMBER(I27),IF(ISNUMBER(J27),J27-I27,""),"–") -> 0
A28: 25 | B28: Veidekke Industri AS – Sogn(60309) | C28: Aktiv | D28: Standardtabell 0-99 | E28: kr 2 960 / mnd | F28: 0–99 samtaler | G28: Kø 4509 · Oppstart mars 2026. Kunde 33197 | H28: 42 | I28: =IF(H28="–","–",IFERROR(VLOOKUP(H28,Tabeller!$A$2:$B$35,2,TRUE()),2960)) -> 2960 | J28: 2960 | K28: =IF(ISNUMBER(I28),IF(ISNUMBER(J28),J28-I28,""),"–") -> 0
A30: FAST PRIS + STYKKPRIS (individuelle avtaler)
A31: 26 | B31: Advokat Henjum AS | C31: Aktiv | D31: Fast pris kr 920 + stykkpris kr 46/anrop | E31: kr 920 / mnd inkl. 20 anrop + kr 46 / anrop over 20 | F31: 0–20 anrop | G31: Feilaktig markert sagt opp – aktiv per juni 2026 | H31: 20 | I31: =IF(H31="–",920,920+MAX(0,H31-20)*46) -> 920 | J31: 920 | K31: =IF(ISNUMBER(I31),IF(ISNUMBER(J31),J31-I31,""),"–") -> 0
A32: 27 | B32: Compass Group Norge AS (Veidekke-hovednummer) | C32: Aktiv | D32: Fast pris kr 1700 inkludert 800 anrop + stykkpris per anrop over 800 er kr 26 | E32: kr 17 000 / mnd inkl. 800 anrop + kr 26 / over 800 | F32: 0–800 anrop | G32: Kø 3082 · Juni: 475 anrop + 1 776 e-poster × kr 10 = kr 17 760. Bekreftet av Geir | H32: 457 | I32: =IF(H32="–","–",17000+MAX(0,H32-800)*26) -> 17000 | J32: 17000 | K32: =IF(ISNUMBER(I32),IF(ISNUMBER(J32),J32-I32,""),"–") -> 0
A33: 28 | B33: Veidekke – e-posthåndtering | C33: Aktiv | D33: Stykkpris kr 10 per e-post | E33: kr 10 / e-post (telles manuelt) | F33: Per videresendelse | G33: Tillegg i Compass Group-fakturaen – faktureres separat for å håndtere e-postene | H33: 1662 | I33: 16620 | J33: 16620 | K33: =IF(ISNUMBER(I33),IF(ISNUMBER(J33),J33-I33,""),"–") -> 0
A34: 29 | B34: Frano AS | C34: Aktiv | D34: Fast pris kr 195 + stykkpris kr 29 per anrop | E34: kr 195 fast / mnd + kr 29 / anrop | F34: Ingen inkludert | H34: 9 | I34: =IF(H34="–","–",195+H34*29) -> 456 | J34: 456 | K34: =IF(ISNUMBER(I34),IF(ISNUMBER(J34),J34-I34,""),"–") -> 0
A35: 30 | B35: Funksjonell Medisinsk Klinikk AS | C35: Aktiv | D35: Fast pris kr 840 20 anrop inkl + stykkpris per anrop over 20 er kr 42 | E35: kr 840 / mnd inkl. 20 anrop + kr 42 / anrop over 20 (betaler alltid grunnpris) | F35: 0–20 anrop | G35: 13 anrop i juni · Betaler alltid 840 grunnpris uansett volum | H35: 25 | I35: 1050 | J35: 1050 | K35: =IF(ISNUMBER(I35),IF(ISNUMBER(J35),J35-I35,""),"–") -> 0
A36: 31 | B36: Fysiodirekte AS | C36: Aktiv | D36: kr 805 / mnd inkl. 20 anrop + kr 40 / anrop over 20 (betaler alltid grunnpris) | E36: kr 805 / mnd inkl. 20 anrop + kr 40 / anrop over 20 (betaler alltid grunnpris) | F36: 0–20 anrop | G36: Betaler grunnpris selv uten anrop | H36: 0 | I36: =805 -> 805 | J36: 805 | K36: =IF(ISNUMBER(I36),IF(ISNUMBER(J36),J36-I36,""),"–") -> 0
A37: 32 | B37: Gulvfag Norge AS | C37: Aktiv | D37: kr 700 / mnd inkl. 20 + kr 36 / over 20 + 3 × kr 139 tilknytning | E37: kr 700 / mnd inkl. 20 + kr 36 / over 20 + 3 × kr 139 tilknytning | F37: 0–20 anrop | G37: 3 tillegg: Nye Gulv Norge (1 anrop) + Adler Parkettsliperi (17) + Hytteguttene · Totalt 46 anrop, 26 over 20 | H37: 36 | I37: =IF(H37="–","–",700+MAX(0,H37-20)*36+3*139) -> 1693 | J37: 1693 | K37: =IF(ISNUMBER(I37),IF(ISNUMBER(J37),J37-I37,""),"–") -> 0
A38: 33 | B38: Gunvaldsen og sønn AS | C38: Aktiv | D38: kr 1 180 / mnd inkl. 40 anrop + kr 27 / anrop over 40 | E38: kr 1 180 / mnd inkl. 40 anrop + kr 27 / anrop over 40 | F38: 0–40 anrop | H38: 57 | I38: =IF(H38="–","–",1180+MAX(0,H38-40)*27) -> 1639 | J38: 1639 | K38: =IF(ISNUMBER(I38),IF(ISNUMBER(J38),J38-I38,""),"–") -> 0
A39: 34 | B39: IKT Nor AS | C39: Aktiv | D39: kr 860 / mnd inkl. 20 anrop + kr 42 / anrop over 20 | E39: kr 860 / mnd inkl. 20 anrop + kr 42 / anrop over 20 | F39: 0–20 anrop | H39: 19 | I39: =IF(H39="–","–",860+MAX(0,H39-20)*42) -> 860 | J39: 860 | K39: =IF(ISNUMBER(I39),IF(ISNUMBER(J39),J39-I39,""),"–") -> 0
A40: 35 | B40: Invicta AS | C40: Aktiv | D40: fast pris kr 2 900 / mnd inkludert 200 anrop + stykkpris kr 18 / anrop over 200 | E40: kr 2 900 / mnd base + kr 18 / anrop over 200 | F40: 0–200 anrop | H40: 93 | I40: =IF(H40="–","–",2900+MAX(0,H40-200)*18) -> 2900 | J40: 2900 | K40: =IF(ISNUMBER(I40),IF(ISNUMBER(J40),J40-I40,""),"–") -> 0
A41: 36 | B41: JCDecaux Norge AS | C41: Aktiv | D41: kr 2 000 / mnd inkl. 20 anrop + kr 40 / anrop over 20 (ny pris juni 2026) | E41: kr 2 000 / mnd inkl. 20 anrop + kr 40 / anrop over 20 (ny pris juni 2026) | F41: 0–20 anrop | G41: Ny pris fra juni 2026 (tidl. kr 4 480) | H41: 8 | I41: =IF(H41="–",2000,2000+MAX(0,H41-20)*40) -> 2000 | J41: 2000 | K41: =IF(ISNUMBER(I41),IF(ISNUMBER(J41),J41-I41,""),"–") -> 0
...

Sheet Standard 0-99
A1: Standardtabell 0-99 | F1: 2026
A2: Vol fra | B2: Vol til | F2: Pris
A4: 1 | B4: 99 | F4: 2960
A5: 100 | B5: 149 | F5: 3580
A6: 150 | B6: 199 | F6: 4090
A7: 200 | B7: 249 | F7: 4670
A8: 250 | B8: 299 | F8: 5760
A9: 300 | B9: 349 | F9: 6830
A10: 350 | B10: 399 | F10: 7920
A11: 400 | B11: 449 | F11: 8980
A12: 450 | B12: 499 | F12: 10080
A13: 500 | B13: 549 | F13: 11150
A14: 550 | B14: 599 | F14: 12200
A15: 600 | B15: 649 | F15: 13260
... A37: 2400 | B37: 2499 | F37: 52160

Sheet Fastpris+stykkpris (individuell
A1: FAST PRIS + STYKKPRIS (individuelle avtaler)
A2: Advokat Henjum AS | B2: Aktiv | C2: Fast pris kr 920 + stykkpris kr 46/anrop
A3: Compass Group Norge AS (Veidekke-hovednummer) | B3: Aktiv | C3: Fast pris kr 1700 inkludert 800 anrop + stykkpris per anrop over 800 er kr 26
A4: Veidekke – e-posthåndtering | B4: Aktiv | C4: Stykkpris kr 10 per e-post
A5: Frano AS | B5: Aktiv | C5: Fast pris kr 195 + stykkpris kr 29 per anrop
A6: Funksjonell Medisinsk Klinikk AS | B6: Aktiv | C6: Fast pris kr 840 20 anrop inkl + stykkpris per anrop over 20 er kr 42
A7: Fysiodirekte AS | B7: Aktiv | C7: kr 805 / mnd inkl. 20 anrop + kr 40 / anrop over 20 (betaler alltid grunnpris)
A8: Gulvfag Norge AS | B8: Aktiv | C8: kr 700 / mnd inkl. 20 + kr 36 / over 20 + 3 × kr 139 tilknytning
A9: Gunvaldsen og sønn AS | B9: Aktiv | C9: kr 1 180 / mnd inkl. 40 anrop + kr 27 / anrop over 40
A10: IKT Nor AS | B10: Aktiv | C10: kr 860 / mnd inkl. 20 anrop + kr 42 / anrop over 20
A11: Invicta AS | B11: Aktiv | C11: fast pris kr 2 900 / mnd inkludert 200 anrop + stykkpris kr 18 / anrop over 200
A12: JCDecaux Norge AS | B12: Aktiv | C12: kr 2 000 / mnd inkl. 20 anrop + kr 40 / anrop over 20 (ny pris juni 2026)
A13: Kontroll Elektro AS | B13: Aktiv | C13: kr 860 / mnd inkl. 20 anrop + kr 42 / anrop over 20
... A32: Ower Trafikkskole | B32: Aktiv | C32: Pris pr måned: kr 2 950,- inntil 30 besvarte samtaler Pris per besvart samtale utover 30: kr 60,-

Sheet CEG-tabell
A1: CEG-Tabell
A2: Prisene gjelder per måned og er basert på volum (antall samtaler besvart). Prisene justeres trinnvis etter antall samtaler.
A3: Volum (antall samtaler) | B3: Pris (NOK)
A4: 50 – 69 | B4: 1500
A5: 70 – 89 | B5: 2280
A6: 90 – 109 | B6: 2870
A7: 110 – 129 | B7: 3260
A8: 130 – 149 | B8: 3450
A9: 150 – 169 | B9: 3810
A10: 170 – 189 | B10: 4020
A11: 190 – 209 | B11: 4260
A12: 210 – 229 | B12: 4490
A13: 230 – 249 | B13: 4860
A14: 250 – 269 | B14: 5280
A15: 270 – 289 | B15: 5690
... A123: 2430 – 2449 | B123: 50380

Sheet Caverion
A1: Caverion | C1: 2026
A2: Tabell | B2: 0-99 | C2: 2885
B3: 100-149 | C3: 3303
B4: 150-199 | C4: 3756
B5: 200-249 | C5: 4314
B6: 250-299 | C6: 5315
B7: 300-349 | C7: 6275
B8: 350-399 | C8: 7306
B9: 400-449 | C9: 8308
B10: 450-499 | C10: 9278
B11: 500-549 | C11: 10392
B12: 550-599 | C12: 11228
B13: Tillegg over
B14: >599 | C14: 18

Sheet Fysikalsk institutt
A1: Vika fysikalske institutt
A2: Volum | B2: 2026
A3: 0-30 | B3: 1430
A4: 31-40 | B4: 1640
A5: 41-50 | B5: 1880
A6: 51-60 | B6: 2100
A7: 61-70 | B7: 2300
A8: 71-80 | B8: 2600
A10: Rapporter | B10: fastpris | C10: 790

Sheet Promon tabell
A1: Promon tabell
B2: 2026
A3: 0-99 | B3: 7410
A4: 100-149 | B4: 10550
A5: 150-199 | B5: 13830
A6: 200-249 | B6: 17510

Sheet ENRX tabell
A1: ENRX tabell
A2: 0-99 | B2: 2580
A3: 100-149 | B3: 3100
A4: 150-199 | B4: 3600
A5: 200-249 | B5: 4150
A6: 250-299 | B6: 4640
A7: Over 299: | B7: 32

Sheet Rambøll tabell
A1: Rambøll tabell
B2: Pris 2026
A3: 0 - 99 | B3: 2580
A4: 100-149 | B4: 3090
A5: 150-199 | B5: 3610
A6: 200-249 | B6: 4130
A7: 250-299 | B7: 4640
A9: Pris pr anrop mer enn 299 er kr 42 pr stk.

Sheet Kvartalsfakturering
A2: Fakturaplan Kvartal terminfakturering - Aktive
A4: Kunde | B4: Kunde nr | D4: Produkt | F4: Termin | G4: Fakt dato | I4: Jan | J4: feb | K4: mar | L4: apr | M4: mai | N4: jun | O4: jul | P4: aug | Q4: sep | R4: okt | S4: nov | T4: des
B5: mamut
A8: Element Logic Norge | B8: 32693 | D8: Sentralbord fast | F8: Forskudd pr kvartal 8880,- | G8: 1'ste | I8: x | L8: x | O8: x | R8: x
A10: Element Logic Sverige | B10: 32710 | D10: Sentralbord fast | F10: Forskudd pr kvartal 8880,- eks mva | G10: 1'ste | K10: x | N10: x | Q10: x | T10: x
A12: Norsk yrkesdykkerskole | B12: 30308 | D12: Sentralbord fast | F12: Forskudd pr.kvartal 10230,- | G12: 20'de | J12: x | M12: x | P12: x | S12: x
A14: Norsk Medisinsk Syklotronsenter | D14: Sentralbord fast | F14: Etterskudd pr kvartal 2870,- | G14: 31'de | K14: x | N14: x | Q14: x | T14: x
A16: Feste trafikkskole | D16: Årlig forskudd | F16: 2580,- + (VED BRUK: Daglig pr. dag 380,- Ukentlig bruk(f.eks. ferie) 1490,-) | G16: sep | Q16: x
A18: Compass Group, Trondheim - Enova Powerhouse | B18: 33010 | D18: Sentralbord fast | F18: Forskudd kvartal kr 5140,- | G18: 31'de | I18: x | L18: x | O18: x | R18: x

Sheet Tabeller
A1: STD_Fra | B1: STD_Pris | D1: CEG_Fra | E1: CEG_Pris | G1: CORO_Fra | H1: CORO_Pris | J1: EFAS_Fra | K1: EFAS_Pris | M1: ENRX_Fra | N1: ENRX_Pris | P1: PROMON_Fra | Q1: PROMON_Pris
A2: 0 | B2: 2960 | D2: 0 | E2: 1500 | G2: 0 | H2: 2885 | J2: 0 | K2: 1330 | M2: 0 | N2: 2580 | P2: 0 | Q2: 7410
A3: 100 | B3: 3580 | D3: 70 | E3: 2280 | G3: 100 | H3: 3303 | J3: 31 | K3: 1540 | M3: 100 | N3: 3100 | P3: 100 | Q3: 10550
A4: 150 | B4: 4090 | D4: 90 | E4: 2870 | G4: 150 | H4: 3756 | J4: 41 | K4: 1780 | M4: 150 | N4: 3600 | P4: 150 | Q4: 13830
A5: 200 | B5: 4670 | D5: 110 | E5: 3260 | G5: 200 | H5: 4314 | J5: 51 | K5: 1980 | M5: 200 | N5: 4150 | P5: 200 | Q5: 17510
A6: 250 | B6: 5760 | D6: 130 | E6: 3450 | G6: 250 | H6: 5315 | J6: 61 | K6: 2200 | M6: 250 | N6: 4640
A7: 300 | B7: 6830 | D7: 150 | E7: 3810 | G7: 300 | H7: 6275 | J7: 71 | K7: 2495
A8: 350 | B8: 7920 | D8: 170 | E8: 4020 | G8: 350 | H8: 7306 | J8: 81 | K8: 2850
A9: 400 | B9: 8980 | D9: 190 | E9: 4260 | G9: 400 | H9: 8308
A10: 450 | B10: 10080 | D10: 210 | E10: 4490 | G10: 450 | H10: 9278
A11: 500 | B11: 11150 | D11: 230 | E11: 4860 | G11: 500 | H11: 10392
A12: 550 | B12: 12200 | D12: 250 | E12: 5280 | G12: 550 | H12: 11228
A13: 600 | B13: 13260 | D13: 270 | E13: 5690
A14: 650 | B14: 14360 | D14: 290 | E14: 6100
A15: 700 | B15: 15430 | D15: 310 | E15: 6520
A16: 750 | B16: 16530 | D16: 330 | E16: 6940
A17: 800 | B17: 17590 | D17: 350 | E17: 7370
A18: 850 | B18: 18680 | D18: 370 | E18: 7790
A19: 900 | B19: 19750 | D19: 390 | E19: 8200
A20: 950 | B20: 20820 | D20: 410 | E20: 8610
A21: 1000 | B21: 23000 | D21: 430 | E21: 9020
A22: 1100 | B22: 24100 | D22: 450 | E22: 9440
A23: 1200 | B23: 26260 | D23: 470 | E23: 9860
A24: 1300 | B24: 28400
A25: 1400 | B25: 30240
A26: 1500 | B26: 32710
A27: 1600 | B27: 34890
A28: 1700 | B28: 37060
A29: 1800 | B29: 39200
A30: 1900 | B30: 41380
A31: 2000 | B31: 43500
A32: 2100 | B32: 45650
A33: 2200 | B33: 47850
A34: 2300 | B34: 49980
A35: 2400 | B35: 52160
