Workbook

Sheet Termintabell
A2: Fakturaplan terminfakturering - Aktive
A4: Kunde | B4: Kunde nr | D4: Produkt | F4: Termin | G4: Fakt dato | I4: Jan | J4: feb | K4: mar | L4: apr | M4: mai | N4: jun | O4: jul | P4: aug | Q4: sep | R4: okt | S4: nov | T4: des
B5: mamut
A8: Element Logic Norge | B8: 32693 | D8: Sentralbord fast | F8: Forskudd pr kvartal 8880,- | G8: 1'ste | I8: x | L8: x | O8: x | R8: x
A10: Element Logic Sverige | B10: 32710 | D10: Sentralbord fast | F10: Forskudd pr kvartal 8880,- eks mva | G10: 1'ste | K10: x | N10: x | Q10: x | T10: x
A12: Norsk yrkesdykkerskole | B12: 30308 | D12: Sentralbord fast | F12: Forskudd pr.kvartal 10230,- | G12: 20'de | J12: x | M12: x | P12: x | S12: x
A14: Norsk Medisinsk Syklotronsenter | D14: Sentralbord fast | F14: Etterskudd pr kvartal 2870,- | G14: 31'de | K14: x | N14: x | Q14: x | T14: x
A16: Festa trafikkskole | D16: Årlig forskudd | F16: 2580,- | G16: sep | Q16: x
A18: Compass Group, Trondheim - Enova Powerhouse | B18: 33010 | D18: Sentralbord fast | F18: Forskudd kvartal kr 5140,- | G18: 31'de | I18: x | L18: x | O18: x | R18: x

Sheet Felles
B2: Dato | C2: 46265
B4: Måned | C4: August
B7: Tilleggsopplysninger ved fakturering:
B9: Allskog | C9: Månedsstatistikk
B11: KTV | C11: Salgstelefoner
B14: Coromatic | C14: Husk statistikk fra året før
B17: FMG
B19: Garda | C19: Geir sender
B21: NHO | C21: Geir sender
B23: Veidekke | C23: Månedsstatistikk

Sheet ABC Hus
B2: FAKTURAGRUNNLAG SVARTJENESTE
B4: Kunde | C4: ABC Hus | F4: Saksbehandler: | G4: Geir
B5: Kunde nr | C5: 32494
F6: Dato: | G6: =Felles!C2 -> 46265
B8: Kunden referanse
B9: Navn | C9: Anelia Buitelaar | F9: Etablert: | G9: Fast fra jan 2020
B10: Bestillingsnr/merknad: | C10: 90050 | G10: Tidligere av og på kunde
G11: Sagt opp 11/3-25 - 12 mnd - siste faktura sendes 31/3 2026
B12: Vår referanse: | C12: Geir Bodin | F12: Avtale: | G12: Tabell NB!2019 priser i 2020
B15: Kreditt tid (std. 10 dager) | C15: Netto 10 dager
B16: Kreditt tid (avvikende)
L18: +
B20: Leveranse betegnelse | D20: Måned | E20: Antall | F20: Stk pris | H20: Pris x.mva
B22: Sentralbordtjeneste/back up | D22: =Felles!C4 -> August | E22: 1 | F22: 780 | H22: =E22*F22 -> 780
B23: inkl. 20 samtaler
B24: Samtaler > 20 | E24: 0 | F24: =F22/20 -> 39 | H24: =E24*F24 -> 0
B32: Tekst på faktura:
B39: Sum til fakturering kunde eks.mva | H39: =SUM(H22:H38) -> 780

Sheet AdvHenjum
B2: FAKTURAGRUNNLAG SVARTJENESTE
B4: Kunde | C4: Adv. Henjum | F4: Saksbehandler: | G4: Geir
B5: Kunde nr | C5: 32448
F6: Dato: | G6: =Felles!C2 -> 46265
B8: Kunden referanse
B9: Navn | F9: Etablert: | G9: Sept 2014
B10: Bestillingsnr/merknad: | G10: juni 2024 siste mnd
B12: Vår referanse: | C12: Geir Bodin | F12: Avtale: | G12: 640/32
G13: 660/33
G14: Tabell fra juli 2015 til juni 2024
B15: Kreditt tid (std. 10 dager) | C15: Netto 10 dager | G15: 880/44 | H15: fra juli 2024
B16: Kreditt tid (avvikende)
B20: Leveranse betegnelse | D20: Måned | E20: Antall | F20: Stk pris | H20: Pris x.mva
B22: Sentralbordtjeneste | D22: februar | E22: 1 | F22: 920 | H22: =E22*F22 -> 920
B23: Anrop over 20 | E23: 0 | F23: 46 | H23: =E23*F23 -> 0
B32: Tekst på faktura:
B39: Sum til fakturering kunde eks.mva | H39: =SUM(H22:H38) -> 920

Sheet Adv Olga Halvorsen
B2: FAKTURAGRUNNLAG SVARTJENESTE
B4: Kunde | C4: Advokat Olga Halvorsen | F4: Saksbehandler: | G4: Geir
B5: Kunde nr
C6: 985335249 | F6: Dato: | G6: =Felles!C2 -> 46265
B8: Kunden referanse
B9: Navn | F9: Etablert: | G9: Jan 2015
B10: Bestillingsnr/merknad:
B12: Vår referanse: | C12: Geir Bodin | F12: Avtale: | G12: tabell 0-99 | N12: 2026
I13: Vol fra | J13: Vol til | N13: Pris
B15: Kreditt tid (std. 10 dager) | C15: Netto 10 dager | I15: 1 | J15: 99 | N15: 2960
B16: Kreditt tid (avvikende) | I16: 100 | J16: 149 | N16: 3580
I17: 150 | J17: 199 | N17: 4090
I18: 200 | J18: 249 | N18: 4670
I19: 250 | J19: 299 | N19: 5760
B20: Leveranse betegnelse | D20: Måned | E20: Antall | F20: Stk pris | H20: Pris x.mva | I20: 300 | J20: 349 | N20: 6830
I21: 350 | J21: 399 | N21: 7920
B22: Sentralbord | D22: Februar | E22: 1 | F22: 2960 | H22: =E22*F22 -> 2960 | I22: 400 | J22: 449 | N22: 8980
I23: 450 | J23: 499 | N23: 10080
I24: 500 | J24: 549 | N24: 11150
I25: 550 | J25: 599 | N25: 12200
I26: 600 | J26: 649 | N26: 13260
I27: 650 | J27: 699 | N27: 14360
I28: 700 | J28: 749 | N28: 15430
I29: 750 | J29: 799 | N29: 16530
I30: 800 | J30: 849 | N30: 17590
I31: 850 | J31: 899 | N31: 18680
B32: Tekst på faktura: | I32: 900 | J32: 949 | N32: 19750
I33: 950 | J33: 999 | N33: 20820
I34: 1000 | J34: 1099 | N34: 23000
I35: 1100 | J35: 1199 | N35: 24100
I36: 1200 | J36: 1299 | N36: 26260
I37: 1300 | J37: 1399 | N37: 28400
I38: 1400 | J38: 1499 | N38: 30240
B39: Sum til fakturering kunde eks.mva | H39: =SUM(H22:H38) -> 2960 | I39: 1500 | J39: 1599 | N39: 32710
I40: 1600 | J40: 1699 | N40: 34890
I41: 1700 | J41: 1799 | N41: 37060
I42: 1800 | J42: 1899 | N42: 39200
I43: 1900 | J43: 1999 | N43: 41380
I44: 2000 | J44: 2099 | N44: 43500
I45: 2100 | J45: 2199 | N45: 45650
...

Sheet Adv Sandra
B2: FAKTURAGRUNNLAG SVARTJENESTE
B4: Kunde | C4: Advokat Sandra Latotinaite | F4: Saksbehandler: | G4: Geir
C5: (Moneyback )
B6: Kunde nr | C6: 32518 | F6: Dato: | G6: =Felles!C2 -> 46265
B8: Kunden referanse
B9: Navn | F9: Etablert: | G9: Feb 2015
B10: Bestillingsnr/merknad: | F10: Avsluttet | G10: 42948
B12: Vår referanse: | C12: Geir Bodin | F12: Avtale: | G12: tabell 0-99 | N12: 2026
I13: Vol fra | J13: Vol til | N13: Pris
B15: Kreditt tid (std. 10 dager) | C15: Netto 10 dager | F15: Av og på kunde | I15: 1 | J15: 99 | N15: 2960
B16: Kreditt tid (avvikende) | I16: 100 | J16: 149 | N16: 3580
I17: 150 | J17: 199 | N17: 4090
I18: 200 | J18: 249 | N18: 4670
I19: 250 | J19: 299 | N19: 5760
B20: Leveranse betegnelse | E20: Antall | F20: Stk pris | H20: Pris x.mva | I20: 300 | J20: 349 | N20: 6830
I21: 350 | J21: 399 | N21: 7920
B22: Sentralbordtjeneste | D22: =Felles!C4 -> August | E22: 1 | F22: 2960 | H22: =E22*F22 -> 2960 | I22: 400 | J22: 449 | N22: 8980
I23: 450 | J23: 499 | N23: 10080
I24: 500 | J24: 549 | N24: 11150
I25: 550 | J25: 599 | N25: 12200
I26: 600 | J26: 649 | N26: 13260
I27: 650 | J27: 699 | N27: 14360
I28: 700 | J28: 749 | N28: 15430
I29: 750 | J29: 799 | N29: 16530
I30: 800 | J30: 849 | N30: 17590
I31: 850 | J31: 899 | N31: 18680
B32: Tekst på faktura: | I32: 900 | J32: 949 | N32: 19750
I33: 950 | J33: 999 | N33: 20820
I34: 1000 | J34: 1099 | N34: 23000
I35: 1100 | J35: 1199 | N35: 24100
I36: 1200 | J36: 1299 | N36: 26260
I37: 1300 | J37: 1399 | N37: 28400
I38: 1400 | J38: 1499 | N38: 30240
B39: Sum til fakturering kunde eks.mva | H39: =SUM(H22:H38) -> 2960 | I39: 1500 | J39: 1599 | N39: 32710
I40: 1600 | J40: 1699 | N40: 34890
I41: 1700 | J41: 1799 | N41: 37060
I42: 1800 | J42: 1899 | N42: 39200
I43: 1900 | J43: 1999 | N43: 41380
I44: 2000 | J44: 2099 | N44: 43500
I45: 2100 | J45: 2199 | N45: 45650
...

Sheet Ahlberg data
B2: FAKTURAGRUNNLAG SVARTJENESTE
B4: Kunde | C4: PC Vennen (Ahlberg data) | F4: Saksbehandler:
B9: Kunde nr | C9: 32942
F10: Dato: | G10: =Felles!C2 -> 46265
B12: Kunden referanse | C12: G.Skallerud | F12: Oppstart: aug 2022
B13: Navn
B14: Bestillingsnr/merknad:
F15: Egen prismodell | H15: Ny 2024 | I15: Ny 2025 | J15: Ny 2026
B16: Vår referanse: | C16: Geir Bodin | F16: 0-99 | G16: 3035 | H16: 3310 | I16: 3390 | J16: 3490
F17: Anrop over 99 | G17: 30 | H17: 30 | I17: 31 | J17: 32
B19: Kreditt tid (std. 10 dager) | C19: Netto 10 dager
B20: Kreditt tid (avvikende)
B24: Leveranse betegnelse | E24: Antall | F24: Stk pris | H24: Pris x.mva
B26: Svartjeneste | D26: Februar | E26: 1 | F26: 3490 | H26: =E26*F26 -> 3490
B27: Anrop over 99 | E27: 0 | F27: 32 | H27: =E27*F27 -> 0
B32: Tekst på faktura:
B39: Sum til fakturering kunde eks.mva | H39: =SUM(H26:H38) -> 3490

Sheet Alivia Sagt opp
B2: FAKTURAGRUNNLAG SVARTJENESTE
B4: Kunde | C4: Alivia Insurance AB | F4: Saksbehandler: | G4: Geir
B5: Kunde nr | C5: 33111
F6: Dato: | G6: =Felles!C2 -> 46265
B8: Kunden referanse
B9: Navn | C9: Jonathan Furst | F9: Ny kunde: mars 2023
B10: Bestillingsnr/merknad: | F10: Sagt opp 20/3-25 -1 mnd siste faktura i april.
F11: Tabell: 0-99
B12: Vår referanse: | C12: Geir Bodin
F13: Back up tjeneste/sikkerhet
B15: Kreditt tid (std. 10 dager) | C15: 10 dager
B16: Kreditt tid (avvikende) | C16: _______ dager | F16: Anorp "0"
B20: Leveranse betegnelse | E20: Antall | F20: Stk pris | H20: Pris x.mva
B22: Svartjeneste | D22: =Felles!C4 -> August | E22: 0 | F22: 2500 | H22: =E22*F22 -> 0
B31: Sum til fakturering kunde eks.mva | H31: =SUM(H22:H30) -> 0

Sheet Allskog
B2: FAKTURAGRUNNLAG SVARTJENESTE
B4: Kunde | C4: Allskog | F4: Saksbehandler:
B9: Kunde nr | C9: 32498
F10: Dato: | G10: =Felles!C2 -> 46265
B12: Kunden referanse | F12: Etablert: desember 2014 | J12: Egen tabell | K12: 0-99 | L12: 2930
B13: Navn | K13: 100-149 | L13: 3340
B14: Bestillingsnr/merknad: | K14: 150-199 | L14: 3550
F15: Kjetil legger loggen i mappen: | K15: 200-249 | L15: 3870
B16: Vår referanse: | C16: Geir Bodin | F16: C:\Users\hei\We4you AS\We4you - Internt Sharepoint\statistikk\2025 | K16: 250-299 | L16: 4620
K17: 300-349 | L17: 5490
F18: Statistikk og loggen sendes: | K18: 350-399 | L18: 6360
B19: Kreditt tid (std. 10 dager) | C19: Netto 10 dager | F19: Ellen.Govatsmark@allskog.no og karin.hokstad@allskog.no | K19: 400-449 | L19: 7230
B20: Kreditt tid (avvikende) | K20: 450-499 | L20: 8090
F21: EHF - referanse | K21: 500-549 | L21: 8950
K22: 550-599 | L22: 9820
K23: 600-649 | L23: 10670
B24: NY PRIS MARS 2026 Kr 15.000,- inkl statistikk | K24: 650-699 | L24: 11540
K25: 700-749 | L25: 12400
K26: 750-799 | L26: 13280
K27: 800-849 | L27: 14130
K28: 850-899 | L28: 15000
K29: 900-949 | L29: 15870
B30: Allskog skal ha en egen månedsstatistikk over opptellingen av vår egne registreringer. | K30: 950-999 | L30: 16740
B31: Kjetil tar ut en månedsoversikt i excel. Denne sorteres på dato og aktivitet. Antallet telles opp manuelt og føres manuelt inn i egen logg for allskog!
B32: Det sendes en epost til Allskog som inneholder begge statistikkene fra zisson+vår egenproduserte statistikk for siste måned.
G33: Totalt | H33: 15000
D37: aug | E37: sep | F37: des | G37: jan | H37: feb
B38: allskog | C38: 188 | D38: 295 | E38: 257 | F38: 267 | G38: 426 | H38: 432
B39: Allskog tilbake | C39: 14 | D39: 37 | E39: 33 | F39: 13 | G39: 36 | H39: 19
C40: =SUM(C38:C39) -> 202 | D40: =SUM(D38:D39) -> 332 | E40: =SUM(E38:E39) -> 290 | F40: =SUM(F38:F39) -> 280 | G40: =SUM(G38:G39) -> 462 | H40: =SUM(H38:H39) -> 451
C42: mars | D42: april | E42: mai | G42: Juli | H42: August
B43: allskog | C43: 484 | D43: 485 | E43: 351 | G43: 225 | H43: 281
B44: alskog tilbak | C44: 24 | D44: 19 | E44: 22 | G44: 30 | H44: 27
C45: =SUM(C43:C44) -> 508 | D45: =SUM(D43:D44) -> 504 | E45: =SUM(E43:E44) -> 373 | G45: =SUM(G43:G44) -> 255 | H45: =SUM(H43:H44) -> 308
C48: Sept | D48: Okt | E48: Nov | F48: des
B49: allskog | C49: 369 | D49: 380 | E49: 270
B50: allskog tilbak | C50: 27 | D50: 66 | E50: 30
C52: =SUM(C49:C50) -> 396 | D52: =SUM(D49:D50) -> 446 | E52: =SUM(E49:E50) -> 300 | F52: =SUM(F49:F50) -> 0 | G52: =SUM(G49:G50) -> 0 | H52: =SUM(H49:H50) -> 0
A54: 2026 | C54: Jan | D54: Feb | E54: Mars | F54: April | G54: Mai | H54: Juni | I54: Juli | J54: August
B55: Allskog | C55: 562 | D55: 477 | E55: 712 | F55: 472 | G55: 364 | H55: 405 | I55: 254 | J55: 394
...

Sheet Meavia - Bekkestuapsyk
B2: FAKTURAGRUNNLAG SVARTJENESTE
B4: Kunde | C4: Meavia AS/Bekkestua psykologen | F4: Saksbehandler: | G4: Geir
B5: Kunde nr
F6: Dato: | G6: =Felles!C2 -> 46265
B8: Kunden referanse
B9: Navn | C9: Elisabeth Gislerud | F9: Etablert juli 2018
B10: Bestillingsnr/merknad:
B12: Vår referanse: | C12: Geir Bodin | F12: Egen prisliste (endret oktober 2018)
F14: Grunnpris: | G14: 1380,- (inntil 49 anrop)
B15: Kreditt tid (std. 10 dager) | C15: Netto 10 dager | F15: Anrop > 49 | G15: 36 pr anrop
B16: Kreditt tid (avvikende) | F16: Økning 2020 (3%)
F17: Grunnpris: | G17: 1420 (inntil 49 anrop)
F18: Anrop > 49 | G18: 37 pr anrop
F20: Endret anropspris 2026 til 42 (fra 40,-)
B22: Leveranse betegnelse | E22: Antall | F22: Stk pris | H22: Pris x.mva
B24: Sentralbortjeneste fast | E24: 1 | F24: 199 | H24: =E24*F24 -> 199
B25: Besvarte anrop | E25: 9 | F25: 42 | H25: =E25*F25 -> 378
F26: ,
B27: NB! Betaling pr anrop fra desember 2020
B30: Tekst på faktura:
B37: Sum til fakturering kunde eks.mva | H37: =SUM(H24:H36) -> 577

Sheet Bodyfly
B3: FAKTURAGRUNNLAG SVARTJENESTE
B5: Kunde | C5: Bodyfly Frogner | F5: Saksbehandler: | G5: Geir
B6: Kunde nr | C6: 35526
F7: Dato: | G7: =Felles!C2 -> 46265
B9: Kunden referanse | F9: Avtale oppstart: april/2015
B10: Navn | C10: Rosa Karlsen
B11: Bestillingsnr/merknad: | F11: Grunnpris | G11: 1600 | H11: måned
F12: Variabel | G12: 33 | H12: pr anrop over 99 anrop
B13: Vår referanse: | C13: Geir Bodin
F14: Ny modell fra 2023_ 1600/
B16: Kreditt tid (std. 10 dager) | C16: Netto 10 dager
B17: Kreditt tid (avvikende)
F18: NB Efaktura + statistikk på epost
B21: Leveranse betegnelse | E21: Antall | F21: Stk pris | H21: Pris x.mva
B23: Sentralbordtjeneste | D23: =Felles!C4 -> August | E23: 1 | F23: 1600 | H23: =E23*F23 -> 1600
B24: Tillegg ordre | E24: 0 | F24: 0 | H24: =E24*F24 -> 0
B26: Statistikk til : post@bodyflyfrogner.no
B29: Tekst på faktura:
B36: Sum til fakturering kunde eks.mva | H36: =SUM(H23:H35) -> 1600

Sheet Caverion
B2: FAKTURAGRUNNLAG SVARTJENESTE
B4: Kunde | C4: Caverion Norge AS | F4: Saksbehandler:
B9: Kunde nr | C9: 32952
F10: Dato: | G10: =Felles!C2 -> 46265
B12: Kunden referanse | F12: Oppstart: Mai 2020
B13: Navn | C13: Linda Hertaas
B14: Bestillingsnr/merknad: | C14: 19926600
F15: Egen tabell | G15: se under
B16: Vår referanse: | C16: Geir Bodin
B19: Kreditt tid (std. 10 dager) | C19: Netto 60 dager
B20: Kreditt tid (avvikende)
B24: Leveranse betegnelse | E24: Antall | F24: Stk pris | H24: Pris x.mva
B26: Svartjeneste | C26: =Felles!C4 -> August | D26: inntil 349 anrop | E26: 1 | F26: 5315 | G26: 1 | H26: =SUM(F26)*G26 -> 5315
B27: Anrop > 599 | E27: 0 | F27: 18 | H27: =SUM(E27)*F27 -> 0
B29: Statistikk til: vivian.erster@caverion.com og Lisa.Johansson@caverion.com
B34: Sum til fakturering kunde eks.mva | H34: =SUM(H26:H33) -> 5315
B39: Caverion pristabell | E39: Husk pristabell sendes til Lisa årlig
B40: -indeksregulert
J41: 0.032
C42: 2020 | D42: 2021 | E42: 2022 | F42: 2023 | G42: 2024 | H42: 2025 | I42: 2026
A43: Tabell | B43: 0-99 | C43: 2360 | D43: 2410 | E43: 2490 | F43: 2610 | G43: 2740 | H43: 2795 | I43: 2885
B44: 100-149 | C44: 2700 | D44: 2750 | E44: 2850 | F44: 2990 | G44: 3140 | H44: 3200 | I44: 3303
B45: 150-199 | C45: 3070 | D45: 3130 | E45: 3240 | F45: 3400 | G45: 3570 | H45: 3640 | I45: 3756
B46: 200-249 | C46: 3510 | D46: 3580 | E46: 3710 | F46: 3900 | G46: 4100 | H46: 4180 | I46: 4314
B47: 250-299 | C47: 4330 | D47: 4420 | E47: 4580 | F47: 4810 | G47: 5050 | H47: 5150 | I47: 5315
B48: 300-349 | C48: 5131 | D48: 5230 | E48: 5410 | F48: 5680 | G48: 5960 | H48: 6080 | I48: 6275
B49: 350-399 | C49: 5960 | D49: 6080 | E49: 6290 | F49: 6610 | G49: 6940 | H49: 7080 | I49: 7306
B50: 400-449 | C50: 6760 | D50: 6900 | E50: 7140 | F50: 7520 | G50: 7890 | H50: 8050 | I50: 8308
B51: 450-499 | C51: 7580 | D51: 7730 | E51: 8000 | F51: 8400 | G51: 8820 | H51: 8990 | I51: 9278
B52: 500-549 | C52: 8390 | D52: 8560 | E52: 8860 | F52: 9300 | G52: 9870 | H52: 10070 | I52: 10392
B53: 550-599 | C53: 9190 | D53: 9370 | E53: 9690 | F53: 10170 | G53: 10670 | H53: 10880 | I53: 11228
B54: Tillegg over
B55: >599 | C55: 14,- | D55: 14,- | E55: 15,- | F55: 16.- | G55: 16,- | H55: 17 | I55: 18

Sheet Calpro
B2: FAKTURAGRUNNLAG SVARTJENESTE
B4: Kunde | C4: Calpro AS | F4: Saksbehandler:
B9: Kunde nr | C9: 31896
F10: Dato: | G10: =Felles!C2 -> 46265
B12: Kunden referanse | F12: Oppstart: 12.12.2011
B13: Navn | C13: Kris Sikorski
B14: Bestillingsnr/merknad:
F15: Tabell
B16: Vår referanse: | C16: Geir Bodin
F17: Endret til 0-99 fra jan 2019
B19: Kreditt tid (std. 10 dager) | C19: Netto 10 dager | F19: Ny epost adresse fra 1 nov 2022
B20: Kreditt tid (avvikende)
B24: Leveranse betegnelse | E24: Antall | F24: Stk pris | H24: Pris x.mva | O24: 2026
J25: Vol fra | K25: Vol til | O25: Pris
B26: Svartjeneste | D26: =Felles!C4 -> August | E26: 1 | F26: 2960 | G26: 1 | H26: =SUM(F26)*G26 -> 2960
J27: 1 | K27: 99 | O27: 2960
B28: Statistikk: kris.sikorski@svarlifescience.com | J28: 100 | K28: 149 | O28: 3580
J29: 150 | K29: 199 | O29: 4090
J30: 200 | K30: 249 | O30: 4670
J31: 250 | K31: 299 | O31: 5760
B32: Tekst på faktura: | J32: 300 | K32: 349 | O32: 6830
J33: 350 | K33: 399 | O33: 7920
J34: 400 | K34: 449 | O34: 8980
J35: 450 | K35: 499 | O35: 10080
J36: 500 | K36: 549 | O36: 11150
J37: 550 | K37: 599 | O37: 12200
J38: 600 | K38: 649 | O38: 13260
B39: Sum til fakturering kunde eks.mva | H39: =SUM(H26:H38) -> 2960 | J39: 650 | K39: 699 | O39: 14360
J40: 700 | K40: 749 | O40: 15430
J41: 750 | K41: 799 | O41: 16530
J42: 800 | K42: 849 | O42: 17590
J43: 850 | K43: 899 | O43: 18680
J44: 900 | K44: 949 | O44: 19750
J45: 950 | K45: 999 | O45: 20820
J46: 1000 | K46: 1099 | O46: 23000
J47: 1100 | K47: 1199 | O47: 24100
J48: 1200 | K48: 1299 | O48: 26260
J49: 1300 | K49: 1399 | O49: 28400
J50: 1400 | K50: 1499 | O50: 30240
J51: 1500 | K51: 1599 | O51: 32710
...

Sheet Constuction Equipment Group
A3: FAKTURAGRUNNLAG SVARTJENESTE
A5: Kunde | B5: CEG Norway | E5: Saksbehandler: | F5: Geir
A6: Kunde nr | B6: 33192
E7: Dato: | F7: 45962
A9: Kunden referanse | E9: Avtale oppstart: nov 2025
A10: Navn | B10: Tor Kjetilson Moe
A11: Bestillingsnr/merknad: | E11: Grunnpris | G11: måned
E12: Variabel
A13: Vår referanse: | B13: Geir Bodin
A16: Kreditt tid (std. 10 dager) | B16: Netto 10 dager
A17: Kreditt tid (avvikende) | E17: Endret til tabell 0-99
E18: NB EHF faktura + statistikk på epost
A21: Leveranse betegnelse | D21: Antall | E21: Stk pris | G21: Pris x.mva | I21: Volum (antall samtaler) | J21: Pris (NOK)
I22: 0 – 69 | J22: 1500
A23: Sentralbordtjeneste | C23: 70-89 anrop | D23: 1 | E23: 1500 | G23: =D23*E23 -> 1500 | I23: 70 – 89 | J23: 2280
I24: 90 – 109 | J24: 2870
I25: 110 – 129 | J25: 3260
A26: Statistikk til : tkm@cegroup.no | I26: 130 – 149 | J26: 3450
I27: 150 – 169 | J27: 3810
I28: 170 – 189 | J28: 4020
A29: Tekst på faktura: | I29: 190 – 209 | J29: 4260
I30: 210 – 229 | J30: 4490
I31: 230 – 249 | J31: 4860
I32: 250 – 269 | J32: 5280
I33: 270 – 289 | J33: 5690
I34: 290 – 309 | J34: 6100
I35: 310 – 329 | J35: 6520
A36: Sum til fakturering kunde eks.mva | G36: =SUM(G23:G35) -> 1500 | I36: 330 – 349 | J36: 6940
I37: 350 – 369 | J37: 7370
A38: Pristabell 2025 | I38: 370 – 389 | J38: 7790
B39: Anrop | C39: pris | I39: 390 – 409 | J39: 8200
B40: 0-69 | C40: 1500 | I40: 410 – 429 | J40: 8610
B41: 70-89 | C41: 2280 | I41: 430 – 449 | J41: 9020
B42: 90-109 | C42: 2870 | I42: 450 – 469 | J42: 9440
B43: 110-129 | C43: 3260 | I43: 470 – 489 | J43: 9860
B44: 130-149 | C44: 3450 | I44: 490 – 509 | J44: 10280
B45: 150-169 | C45: 3810 | I45: 510 – 529 | J45: 10700
B46: 170-189 | C46: 4020 | I46: 530 – 549 | J46: 11120
B47: 210-229 | C47: 4260 | I47: 550 – 569 | J47: 11530
B48: 230-249 | C48: 4490 | I48: 570 – 589 | J48: 11940
...

Sheet Coromatic
A2: FAKTURAGRUNNLAG SVARTJENESTE
A4: Kunde | B4: Coromatic | E4: Saksbehandler: | F4: Geir
A5: Kunde nr | B5: 3232
E6: Dato: | F6: =Felles!C2 -> 46265
A8: Kunden referanse
A9: Navn | B9: Tone Sørensen
A10: Bestillingsnr/merknad: | B10: 990 | E10: NB! Huske ny adresse, Postboks 777, Kolbotn
E11: Alternativt epost: faktura@coromatic.no
A12: Vår referanse: | B12: Geir Bodin
A15: Kreditt tid (std. 10 dager) | B15: Netto 10 dager | E15: Oppstart: Test november, rullet vider desember
A16: Kreditt tid (avvikende) | E16: Første faktura, kjør hele desember
E17: Tabell 0-99
A20: Leveranse betegnelse | D20: Antall | E20: Stk pris | G20: Pris x.mva | N20: 2026
I21: Vol fra | J21: Vol til | N21: Pris
A22: Sentralbordtjeneste | C22: =Felles!C4 -> August | D22: 1 | E22: 3580 | G22: 3580
I23: 1 | J23: 99 | N23: 2960
I24: 100 | J24: 149 | N24: 3580
I25: 150 | J25: 199 | N25: 4090
I26: 200 | J26: 249 | N26: 4670
I27: 250 | J27: 299 | N27: 5760
I28: 300 | J28: 349 | N28: 6830
I29: 350 | J29: 399 | N29: 7920
I30: 400 | J30: 449 | N30: 8980
I31: 450 | J31: 499 | N31: 10080
I32: 500 | J32: 549 | N32: 11150
I33: 550 | J33: 599 | N33: 12200
I34: 600 | J34: 649 | N34: 13260
... I56: 2400 | J56: 2499 | N56: 52160

Sheet Dal Media
B2: FAKTURAGRUNNLAG SVARTJENESTE
B4: Kunde | C4: Dal Media (tidl.FX Norge og DMG) | F4: Saksbehandler: | G4: Geir
B5: Kunde nr | D5: 32912
F6: Dato: | G6: =Felles!C2 -> 46265
B8: Kunden referanse
B9: Navn | C9: Thomas Dalby | F9: Tabell | G9: 0-99
B10: Bestillingsnr/merknad:
F11: Faktura: | G11: PDF m/statistikk
B12: Vår referanse: | C12: Geir Bodin
B15: Kreditt tid (std. 10 dager) | C15: Netto 10 dager
B16: Kreditt tid (avvikende)
B20: Leveranse betegnelse | E20: Antall | F20: Stk pris | H20: Pris x.mva | O20: 2026
J21: Vol fra | K21: Vol til | O21: Pris
B22: Sentralbordtjeneste | D22: =Felles!C4 -> August | E22: 1 | F22: 4670 | H22: 4670
J23: 1 | K23: 99 | O23: 2960
B24: Tillegg TD Caravan og service | E24: 1 | F24: 199 | H24: =E24*F24 -> 199 | J24: 100 | K24: 149 | O24: 3580
J25: 150 | K25: 199 | O25: 4090
B26: Tillegg Saltando | E26: 1 | F26: 199 | H26: =E26*F26 -> 199 | J26: 200 | K26: 249 | O26: 4670
J27: 250 | K27: 299 | O27: 5760
B28: Tillegg Victoria | E28: 1 | F28: 199 | H28: 199 | J28: 300 | K28: 349 | O28: 6830
J29: 350 | K29: 399 | O29: 7920
J30: 400 | K30: 449 | O30: 8980
J31: 450 | K31: 499 | O31: 10080
B32: Tekst på faktura: | J32: 500 | K32: 549 | O32: 11150
J33: 550 | K33: 599 | O33: 12200
J34: 600 | K34: 649 | O34: 13260
J35: 650 | K35: 699 | O35: 14360
J36: 700 | K36: 749 | O36: 15430
J37: 750 | K37: 799 | O37: 16530
J38: 800 | K38: 849 | O38: 17590
B39: Sum til fakturering kunde eks.mva | H39: =SUM(H22:H38) -> 5267 | J39: 850 | K39: 899 | O39: 18680
J40: 900 | K40: 949 | O40: 19750
C41: Jan | D41: Feb | E41: Mar | F41: Apr | G41: Mai | H41: Jun | J41: 950 | K41: 999 | O41: 20820
B42: DMG | C42: 78 | D42: 82 | E42: 93 | F42: 79 | G42: 99 | H42: 135 | J42: 1000 | K42: 1099 | O42: 23000
B43: TDC | C43: 2 | D43: 1 | E43: 3 | F43: 9 | G43: 29 | H43: 15 | J43: 1100 | K43: 1199 | O43: 24100
B44: Saltando | H44: 10 | J44: 1200 | K44: 1299 | O44: 26260
C45: =SUM(C42:C44) -> 80 | D45: =SUM(D42:D44) -> 83 | E45: =SUM(E42:E44) -> 96 | F45: =SUM(F42:F44) -> 88 | G45: =SUM(G42:G44) -> 128 | H45: =SUM(H42:H44) -> 160 | J45: 1300 | K45: 1399 | O45: 28400
J46: 1400 | K46: 1499 | O46: 30240
C47: jul | D47: aug | E47: sep | F47: okt | G47: nov | H47: des | J47: 1500 | K47: 1599 | O47: 32710
B48: DMG | C48: 54 | D48: 103 | E48: 76 | F48: 68 | G48: 85 | H48: 57 | J48: 1600 | K48: 1699 | O48: 34890
...

Sheet Akkodis - Datarespons
B2: FAKTURAGRUNNLAG SVARTJENESTE
B4: Kunde | C4: Akkodis - Data Respons | F4: Saksbehandler: | G4: Geir Bodin
B9: Kunde nr
F10: Dato: | G10: =Felles!C2 -> 46265
B12: Kunden referanse
B13: Navn | C13: Karin Bråthen | F13: Etablert | G13: Sept 2016
B14: Bestillingsnr/merknad:
F15: Tall kunde | G15: 2960
B16: Vår referanse: | C16: Geir Bodin | F16: 0-99
B19: Kreditt tid (std. 10 dager) | C19: Netto 10 dager
B20: Kreditt tid (avvikende)
B24: Leveranse betegnelse | E24: Antall | F24: Stk pris | H24: Pris x.mva | O24: 2026
J25: Vol fra | K25: Vol til | O25: Pris
B26: Svartjeneste | E26: 1 | F26: 2960 | H26: =E26*F26 -> 2960
J27: 1 | K27: 99 | O27: 2960
J28: 100 | K28: 149 | O28: 3580
J29: 150 | K29: 199 | O29: 4090
J30: 200 | K30: 249 | O30: 4670
J31: 250 | K31: 299 | O31: 5760
B32: Tekst på faktura: | J32: 300 | K32: 349 | O32: 6830
J33: 350 | K33: 399 | O33: 7920
J34: 400 | K34: 449 | O34: 8980
J35: 450 | K35: 499 | O35: 10080
J36: 500 | K36: 549 | O36: 11150
J37: 550 | K37: 599 | O37: 12200
J38: 600 | K38: 649 | O38: 13260
B39: Sum til fakturering kunde eks.mva | H39: =SUM(H26:H38) -> 2960 | J39: 650 | K39: 699 | O39: 14360
J40: 700 | K40: 749 | O40: 15430
J41: 750 | K41: 799 | O41: 16530
J42: 800 | K42: 849 | O42: 17590
J43: 850 | K43: 899 | O43: 18680
J44: 900 | K44: 949 | O44: 19750
J45: 950 | K45: 999 | O45: 20820
J46: 1000 | K46: 1099 | O46: 23000
J47: 1100 | K47: 1199 | O47: 24100
J48: 1200 | K48: 1299 | O48: 26260
J49: 1300 | K49: 1399 | O49: 28400
J50: 1400 | K50: 1499 | O50: 30240
J51: 1500 | K51: 1599 | O51: 32710
... J60: 2400 | K60: 2499 | O60: 52160

Sheet Dental Sør
C3: Kunde | D3: Dental Sør | G3: Saksbehandler: | H3: Geir
C4: Kunde nr | D4: 32244
G5: Dato: | H5: 45987
C7: Kunden referanse
C8: Navn | D8: Aase Johnsen
C9: Bestillingsnr/merknad: | G9: Tabell
C11: Vår referanse: | D11: Geir Bodin
C14: Kreditt tid (std. 10 dager) | D14: Netto 10 dager | G14: Statistikk til:
C15: Kreditt tid (avvikende)
C19: Leveranse betegnelse | F19: Antall | G19: Stk pris | I19: Pris x.mva | K19: Volum (antall samtaler) | L19: Pris (NOK)
K20: 0 – 69 | L20: 1500
C21: Sentralbordtjeneste 0-69 anrop | F21: 1 | G21: 4860 | I21: =F21*G21 -> 4860 | K21: 70 – 89 | L21: 2280
K22: 90 – 109 | L22: 2870
K23: 110 – 129 | L23: 3260
K24: 130 – 149 | L24: 3450
K25: 150 – 169 | L25: 3810
K26: 170 – 189 | L26: 4020
K27: 190 – 209 | L27: 4260
K28: 210 – 229 | L28: 4490
K29: 230 – 249 | L29: 4860
K30: 250 – 269 | L30: 5280
K31: 270 – 289 | L31: 5690
K32: 290 – 309 | L32: 6100
K33: 310 – 329 | L33: 6520
... K35: 350 – 369 | L35: 7370
C36: Sum til fakturering kunde eks.mva | I36: =SUM(I21:I35) -> 4860 | K36: 370 – 389 | L36: 7790
K37: 390 – 409 | L37: 8200
K38: 410 – 429 | L38: 8610
K39: 430 – 449 | L39: 9020
K40: 450 – 469 | L40: 9440
K41: 470 – 489 | L41: 9860
K42: 490 – 509 | L42: 10280
K43: 510 – 529 | L43: 10700
K44: 530 – 549 | L44: 11120
K45: 550 – 569 | L45: 11530
K46: 570 – 589 | L46: 11940
K47: 590 – 609 | L47: 12350
K48: 610 – 629 | L48: 12760
... K142: 2490 – 2499 | L142: 51540

Sheet DomingoSagt opp
B2: FAKTURAGRUNNLAG SVARTJENESTE
B4: Kunde | C4: Domingo | F4: Saksbehandler: | G4: Geir Bodin
C5: organisasjonsnummer 934649206
B9: Kunde nr
F10: Dato: | G10: =Felles!C2 -> 46265
B12: Kunden referanse
B13: Navn | C13: Svein Bjarne Nesbø <svein@sogoshop.no> | F13: Etablert | G13: Mai 2025 | I13: Sagt opp avtale, skal ikke faktureres
B14: Bestillingsnr/merknad:
F15: Tall kunde
B16: Vår referanse: | C16: Geir Bodin | F16: 0-99
B19: Kreditt tid (std. 10 dager) | C19: Netto 10 dager
B20: Kreditt tid (avvikende)
B24: Leveranse betegnelse | E24: Antall | F24: Stk pris | H24: Pris x.mva
B26: Svartjeneste | D26: =Felles!C4 -> August | E26: 0 | F26: 3470 | H26: =E26*F26 -> 0
B32: Tekst på faktura:
B39: Sum til fakturering kunde eks.mva | H39: =SUM(H26:H38) -> 0

Sheet EFAS
B2: FAKTURAGRUNNLAG SVARTJENESTE
B4: Kunde | C4: Eurofusion AS | F4: Saksbehandler: | G4: Geir Bodin
C5: EFAS
F7: Dato: | G7: =Felles!C2 -> 46265
B9: Kunde nr
F10: Etablert | G10: 45231
B12: Kunden referanse | F12: Fast; 199,-abo pr mnd
B13: Navn | C13: Matz Sandberg
B14: Bestillingsnr/merknad: | F14: Volum | G14: 2024 | H14: 2025 | I14: 2026
F15: 0-30 | G15: 1260 | H15: 1290 | I15: 1330
B16: Vår referanse: | C16: Geir Bodin | F16: 31-40 | G16: 1450 | H16: 1490 | I16: 1540
F17: 41-50 | G17: 1670 | H17: 1720 | I17: 1780
F18: 51-60 | G18: 1860 | H18: 1920 | I18: 1980
B19: Kreditt tid (std. 10 dager) | C19: Netto 10 dager | F19: 61-70 | G19: 2080 | H19: 2140 | I19: 2200
B20: Kreditt tid (avvikende) | F20: 71-80 | G20: 2350 | H20: 2420 | I20: 2495
F21: 81-100 (?) | G21: 2680 | H21: 2760 | I21: 2850
B24: Leveranse betegnelse | E24: Antall | F24: Stk pris | H24: Pris x.mva
B26: Svartjeneste | D26: juni | E26: 1 | F26: 1330 | H26: =E26*F26 -> 1330
B32: Tekst på faktura:
B39: Sum til fakturering kunde eks.mva | H39: =SUM(H26:H38) -> 1330

Sheet Element
B2: FAKTURAGRUNNLAG SVARTJENESTE
B4: Kunde | C4: Element Logic AS | F4: Saksbehandler:
B9: Kunde nr | C9: ny
F10: Dato: | G10: =Felles!C2 -> 46265
B12: Kunden referanse
B13: Navn | C13: Rikke Aas | G13: Ny: des/2016
B14: Bestillingsnr/merknad:
G15: Tabell: 0-99
B16: Vår referanse: | C16: Geir Bodin
G17: Fakturer forskudd kvartal (jan/apr/jul/okt)
G18: Avregning volum kvartal
B19: Kreditt tid (std. 10 dager) | C19: Netto 10 dager | G19: 42826 | I19: NB!
B20: Kreditt tid (avvikende) | G20: 42917 | I20: Faktura i EHF
G21: 43009
G22: 42736
B24: Leveranse betegnelse | E24: Antall | F24: Stk pris | H24: Pris x.mva | P24: 2026
K25: Vol fra | L25: Vol til | P25: Pris
B26: Svartjeneste | D26: kvartal | E26: 3 | F26: 2960 | H26: =E26*F26 -> 8880
K27: 1 | L27: 99 | P27: 2960
K28: 100 | L28: 149 | P28: 3580
K29: 150 | L29: 199 | P29: 4090
K30: 200 | L30: 249 | P30: 4670
K31: 250 | L31: 299 | P31: 5760
B32: Tekst på faktura: | K32: 300 | L32: 349 | P32: 6830
K33: 350 | L33: 399 | P33: 7920
K34: 400 | L34: 449 | P34: 8980
K35: 450 | L35: 499 | P35: 10080
K36: 500 | L36: 549 | P36: 11150
K37: 550 | L37: 599 | P37: 12200
K38: 600 | L38: 649 | P38: 13260
B39: Sum til fakturering kunde eks.mva | H39: =SUM(H26:H38) -> 8880 | K39: 650 | L39: 699 | P39: 14360
K40: 700 | L40: 749 | P40: 15430
K41: 750 | L41: 799 | P41: 16530
B42: Jan | C42: 39 | K42: 800 | L42: 849 | P42: 17590
B43: Feb | C43: 67 | D43: 163 tlf , fakturert | K43: 850 | L43: 899 | P43: 18680
B44: Mars | C44: 57 | K44: 900 | L44: 949 | P44: 19750
B45: april | C45: 11 | K45: 950 | L45: 999 | P45: 20820
B46: Mai | C46: 56 | K46: 1000 | L46: 1099 | P46: 23000
B47: Juni | C47: 48 | K47: 1100 | L47: 1199 | P47: 24100
B48: Juli | K48: 1200 | L48: 1299 | P48: 26260
...

Sheet Element Log Sweden
B2: FAKTURAGRUNNLAG SVARTJENESTE
B4: Kunde | C4: Element Logic Sweden | F4: Saksbehandler:
B9: Kunde nr | C9: 32710
F10: Dato: | G10: =Felles!C2 -> 46265
B12: Kunden referanse | G12: Ny: mars 2017
B13: Navn
B14: Bestillingsnr/merknad: | G14: Tabell: 0-99
B16: Vår referanse: | C16: Geir Bodin | G16: Fakturer forskudd kvartal (mars-mai, juni-aug osv)
G17: Første gang 30 mars for mars, april, mai, deretter
G18: 42887
B19: Kreditt tid (std. 10 dager) | C19: Netto 10 dager | G19: 42979 | Q19: 2026
B20: Kreditt tid (avvikende) | G20: 43070 | H20: Fakturer: | L20: Vol fra | M20: Vol til | Q20: Pris
G21: 42795 | H21: Statistikk til:
L22: 1 | M22: 99 | Q22: 2960
L23: 100 | M23: 149 | Q23: 3580
B24: Leveranse betegnelse | E24: Antall | F24: Stk pris | H24: Pris x.mva | L24: 150 | M24: 199 | Q24: 4090
L25: 200 | M25: 249 | Q25: 4670
B26: Svartjeneste | D26: kvartal | E26: 3 | F26: 2960 | H26: =E26*F26 -> 8880 | I26: X MVA | L26: 250 | M26: 299 | Q26: 5760
L27: 300 | M27: 349 | Q27: 6830
B28: Element Logic Norge og Element Logic Sverige skal ha statistikk tilsendt i separate eposter for begge selskaper, | L28: 350 | M28: 399 | Q28: 7920
B29: Sendes til Tommy Nygren på epost: tommy.nygren@elementlogic.no | L29: 400 | M29: 449 | Q29: 8980
L30: 450 | M30: 499 | Q30: 10080
L31: 500 | M31: 549 | Q31: 11150
B32: Tekst på faktura: | L32: 550 | M32: 599 | Q32: 12200
L33: 600 | M33: 649 | Q33: 13260
L34: 650 | M34: 699 | Q34: 14360
L35: 700 | M35: 749 | Q35: 15430
L36: 750 | M36: 799 | Q36: 16530
L37: 800 | M37: 849 | Q37: 17590
L38: 850 | M38: 899 | Q38: 18680
B39: Sum til fakturering kunde eks.mva | H39: =SUM(H26:H38) -> 8880 | L39: 900 | M39: 949 | Q39: 19750
L40: 950 | M40: 999 | Q40: 20820
B41: Tilleggsopplysning | L41: 1000 | M41: 1099 | Q41: 23000
B42: Swift | C42: SPTRNO22 | L42: 1100 | M42: 1199 | Q42: 24100
B43: IBAN | C43: NO49 2291 1519 147 | L43: 1200 | M43: 1299 | Q43: 26260
L44: 1300 | M44: 1399 | Q44: 28400
B45: 2026 | L45: 1400 | M45: 1499 | Q45: 30240
B46: Jan | C46: 20 | L46: 1500 | M46: 1599 | Q46: 32710
B47: Feb | C47: 55 | L47: 1600 | M47: 1699 | Q47: 34890
B48: mars | C48: 33 | L48: 1700 | M48: 1799 | Q48: 37060
...

Sheet ENRX
B2: FAKTURAGRUNNLAG SVARTJENESTE
B4: Kunde | C4: ENRX AS | F4: Saksbehandler: | G4: Geir Bodin
B6: Org nr 930 400 580
B9: Kunde nr | C9: 33150
F10: Dato: | G10: =Felles!C2 -> 46265
B12: Kunden referanse
B13: Navn | F13: Etablert | G13: 45413
B14: Bestillingsnr/merknad:
C15: Sentralbord/HR | F15: Egent tabell | H15: Prisendring 2026
F16: 0-99 | G16: 2500 | H16: 2580
B17: Vår referanse: | C17: Geir Bodin | F17: 100-149 | G17: 3000 | H17: 3100
F18: 150-199 | G18: 3500 | H18: 3600
B19: Kreditt tid (std. 10 dager) | C19: Netto 10 dager | F19: 200-249 | G19: 4000 | H19: 4150
B20: Kreditt tid (avvikende) | F20: 250-299 | G20: 4500 | H20: 4640
F21: Over 299: | G21: 30 | H21: 32
F22: Husk engelsk tekst på faktura
B24: Leveranse betegnelse | E24: Antall | F24: Stk pris | H24: Pris x.mva
B26: Svartjeneste | E26: 1 | F26: 2580 | H26: =F26 -> 2580
F27: lan
B32: Tekst på faktura:
B39: Sum til fakturering kunde eks.mva | H39: =SUM(H26:H38) -> 2580

Sheet Enova
B2: FAKTURAGRUNNLAG SVARTJENESTE
B4: Kunde | C4: Enova Trondheim (COMPASS) | F4: Saksbehandler: | G4: Geir Bodin
B6: Org nr
B9: Kunde nr
F10: Dato: | G10: =Felles!C2 -> 46265
B12: Kunden referanse
B13: Navn | F13: Etablert | G13: 45413 | H13: 2025
B14: Bestillingsnr/merknad:
C15: Sentralbord/HR | E15: Ny prismodell f.o.m. april
E16: Forskudd kvartal kr 4980,- | H16: 5140
B17: Vår referanse: | C17: Geir Bodin | E17: Inkl 200 samtaler.
E18: Eventuelle overskytende faktures
B19: Kreditt tid (std. 10 dager) | C19: Netto 10 dager | E19: etterskuddsvis på neste kvartal
B20: Kreditt tid (avvikende) | E20: kr 36 pr samtale. | H20: 36
E21: faktureres:
E22: april
E23: juli
E24: oktober
E25: januar
B30: Leveranse betegnelse | E30: Antall | F30: Stk pris | H30: Pris x.mva
B32: Svartjeneste | D32: =Felles!C4 -> August | E32: 1 | F32: 5140 | H32: =E32*F32 -> 5140
B38: Tekst på faktura:
B45: Sum til fakturering kunde eks.mva | H45: =SUM(H32:H44) -> 5140
A47: 2026
B48: Jan | C48: 45
B49: Feb | C49: 62
B50: mars
B51: april | C51: 39
B52: mai | C52: 56
B53: juni | C53: 75
B54: juli | C54: 28
B55: august | C55: 66

Sheet Festetrafikk
B2: FAKTURAGRUNNLAG SVARTJENESTE
B4: Kunde | C4: Feste trafikkskole AS | F4: Saksbehandler: | G4: Geir Bodin
B6: Org nr 919 470 356
B9: Kunde nr | C9: 35155
F10: Dato: | G10: =Felles!C2 -> 46265
B12: Kunden referanse
B13: Navn | C13: Beathe Andersen | F13: Etablert | G13: 2024-9
B14: Bestillingsnr/merknad:
F16: Årlig abnm. faktureres september: 2580,- | I16: Neste 01.09.26-30.08.27
B17: Vår referanse: | C17: Geir Bodin
F18: Ved bruk av oss
B19: Kreditt tid (std. 10 dager) | C19: Netto 10 dager | F19: -Daglig pr. dag 380,-
B20: Kreditt tid (avvikende) | F20: -Ukentlig bruk(f.eks. ferie) 1490,-
F21: -Generert rapporter pris pr uke: 210.-
B24: Leveranse betegnelse | E24: Antall | F24: Stk pris | H24: Pris x.mva
B26: Svartjeneste dag | E26: 2 | F26: 380 | H26: =E26*F26 -> 760
B27: alt. Svartjeneste uke | E27: 0 | F27: 1490 | H27: =E27*F27 -> 0
B28: Rapport ukentlig | E28: 1 | F28: 210 | H28: =E28*F28 -> 210
B32: Tekst på faktura:
B39: Sum til fakturering kunde eks.mva | H39: =SUM(H26:H38) -> 970
B41: Statistikk | C41: Besv.anrop

Sheet FirstMovergroup-Totalreform
B2: FAKTURAGRUNNLAG SVARTJENESTE
B4: Kunde | C4: First Mover Group | F4: Saksbehandler:
B5: Kunde nr | C5: 32706
F6: Dato: | G6: =Felles!C2 -> 46265
B8: Kunden referanse
B9: Navn | C9: Fredrik Wessel | H9: Prisendring 2025?
B10: Bestillingsnr/merknad: | C10: Prosjekt 9530 | F10: 42767
F11: Tabell 0-99
B12: Vår referanse: | C12: Geir Bodin
F13: Faktureres EHF
B15: Kreditt tid (std. 10 dager) | C15: Netto 10 dager
B16: Kreditt tid (avvikende)
B20: Leveranse betegnelse | E20: Antall | F20: Stk pris | H20: Pris x.mva | J20: Pristabell sentralbordet gjeldende fra 01.01.-31.12.2026
O22: 2026
B23: Svartjeneste | E23: 1 | F23: 3580 | H23: =E23*F23 -> 3580 | J23: Vol fra | K23: Vol til | O23: Pris
B24: Ekstra tilknytning | E24: 1 | F24: 199 | H24: =E24*F24 -> 199
B25: Office 365 | E25: 1 | F25: 1240 | H25: =E25*F25 -> 1240 | J25: 1 | K25: 99 | O25: 2960
J26: 100 | K26: 149 | O26: 3580
J27: 150 | K27: 199 | O27: 4090
B28: Tekst på faktura: | J28: 200 | K28: 249 | O28: 4670
J29: 250 | K29: 299 | O29: 5760
J30: 300 | K30: 349 | O30: 6830
J31: 350 | K31: 399 | O31: 7920
B32: Statistikk til : heidi.eskerud@firstmovergroup.no | J32: 400 | K32: 449 | O32: 8980
J33: 450 | K33: 499 | O33: 10080
J34: 500 | K34: 549 | O34: 11150
B35: Sum til fakturering kunde eks.mva | H35: =SUM(H23:H34) -> 5019 | J35: 550 | K35: 599 | O35: 12200
J36: 600 | K36: 649 | O36: 13260
J37: 650 | K37: 699 | O37: 14360
J38: 700 | K38: 749 | O38: 15430
J39: 750 | K39: 799 | O39: 16530
J40: 800 | K40: 849 | O40: 17590
J41: 850 | K41: 899 | O41: 18680
J42: 900 | K42: 949 | O42: 19750
J43: 950 | K43: 999 | O43: 20820
J44: 1000 | K44: 1099 | O44: 23000
J45: 1100 | K45: 1199 | O45: 24100
J46: 1200 | K46: 1299 | O46: 26260
J47: 1300 | K47: 1399 | O47: 28400
... J58: 2400 | K58: 2499 | O58: 52160

Sheet Frano
A1: Fran
B3: FAKTURAGRUNNLAG SVARTJENESTE
B5: Kunde | C5: Frano | F5: Saksbehandler: | G5: Geir Bodin
B10: Kunde nr | C10: 33186
F11: Dato: | G11: 45962
B13: Kunden referanse
B14: Navn | C14: Liv Almenningen | F14: Oppstart: | G14: 45962
B15: Bestillingsnr/merknad: | C15: innkjøpsordre 336
B17: Vår referanse: | C17: Geir Bodin
F18: Fakturer EHF
B20: Kreditt tid (std. 10 dager) | C20: Netto 10 dager
B21: Kreditt tid (avvikende)
B25: Leveranse betegnelse | E25: Antall | F25: Stk pris | H25: Pris x.mva
B27: Fastpris for nr og statestikk | D27: =Felles!C5 -> 0 | E27: 1 | F27: 195 | H27: =E27*F27 -> 195
B28: Svartjeneste,antall anrop | E28: 10 | F28: 29 | H28: 290
B30: Statistikk til: lno@noah.no
B34: Tekst på faktura:
B41: Sum til fakturering kunde eks.mva | H41: =SUM(H27:H40) -> 485

Sheet Foma
B2: FAKTURAGRUNNLAG SVARTJENESTE
B4: Kunde | C4: Foma Norge AS | F4: Saksbehandler: | G4: Geir Bodin
B9: Kunde nr | C9: 32803
F10: Dato: | G10: =Felles!C2 -> 46265
B12: Kunden referanse | F12: Etablert: 30 april 2017
B13: Navn | C13: Øystein Gabrielsen
B14: Bestillingsnr/merknad:
F15: Tabell
B16: Vår referanse: | C16: Geir Bodin
B19: Kreditt tid (std. 10 dager) | C19: Netto 10 dager
B20: Kreditt tid (avvikende)
B24: Leveranse betegnelse | E24: Antall | F24: Stk pris | H24: Pris x.mva
J25: Pristabell sentralbordet gjeldende fra 01.01.-31.12.2026
B26: Grunnpris | E26: 1 | F26: 199 | H26: =E26*F26 -> 199
B27: Sentralbordtjeneste | E27: 1 | F27: 6830 | H27: 6830 | O27: 2026
J28: Vol fra | K28: Vol til | O28: Pris
J30: 1 | K30: 99 | O30: 2960
B31: Tekst på faktura: | J31: 100 | K31: 149 | O31: 3580
J32: 150 | K32: 199 | O32: 4090
J33: 200 | K33: 249 | O33: 4670
J34: 250 | K34: 299 | O34: 5760
J35: 300 | K35: 349 | O35: 6830
J36: 350 | K36: 399 | O36: 7920
J37: 400 | K37: 449 | O37: 8980
B38: Sum til fakturering kunde eks.mva | H38: =SUM(H26:H37) -> 7029 | J38: 450 | K38: 499 | O38: 10080
J39: 500 | K39: 549 | O39: 11150
J40: 550 | K40: 599 | O40: 12200
J41: 600 | K41: 649 | O41: 13260
J42: 650 | K42: 699 | O42: 14360
J43: 700 | K43: 749 | O43: 15430
J44: 750 | K44: 799 | O44: 16530
J45: 800 | K45: 849 | O45: 17590
J46: 850 | K46: 899 | O46: 18680
J47: 900 | K47: 949 | O47: 19750
J48: 950 | K48: 999 | O48: 20820
J49: 1000 | K49: 1099 | O49: 23000
J50: 1100 | K50: 1199 | O50: 24100
... J63: 2400 | K63: 2499 | O63: 52160

Sheet Funksjonell
B2: FAKTURAGRUNNLAG SVARTJENESTE
B4: Kunde | C4: Funksjonellmedisinsk Klinikk AS | F4: Saksbehandler: | G4: Geir Bodin
B6: Org nr 922183953
B9: Kunde nr | C9: 33156
F10: Dato: | G10: =Felles!C2 -> 46265
B12: Kunden referanse
B13: Navn | C13: Anders Folven | F13: Etablert | G13: 2024-9
B14: Bestillingsnr/merknad:
F15: Fastpris mnd: 840 | G15: 2025
F16: Inkl. 20: | G16: 840
B17: Vår referanse: | C17: Geir Bodin | F17: Pr anrop over | G17: 42
B19: Kreditt tid (std. 10 dager) | C19: Netto 10 dager
B20: Kreditt tid (avvikende)
B24: Leveranse betegnelse | E24: Antall | F24: Stk pris | H24: Pris x.mva
B26: Svartjeneneste inkl. 20 | D26: =Felles!C4 -> August | E26: 1 | F26: 840 | H26: =E26*F26 -> 840
B27: Pr anop over 20 | E27: 0 | F27: 42 | H27: =E27*F27 -> 0
B32: Tekst på faktura:
B39: Sum til fakturering kunde eks.mva | H39: =SUM(H26:H38) -> 840
B41: Statistikk
B42: 2026
B43: Januar | C43: 32

Sheet Sagt opp Funkweb
B2: FAKTURAGRUNNLAG SVARTJENESTE
B4: Kunde | C4: Funkweb Kompetanse | F4: Saksbehandler: | G4: Geir Bodin
C5: Trondheimsveien 184
C6: 0570 Oslo
B9: Kunde nr
F10: Dato: | G10: =Felles!C2 -> 46265
B12: Kunden referanse | F12: Endret fra Funkweb Aktiv den 27.08.2014
B13: Navn | F13: Sagt opp desember 2024, avsluttet mars 2025
B14: Bestillingsnr/merknad:
F15: 2019 | G15: 660/33
B16: Vår referanse: | C16: Geir Bodin | F16: 2020 | G16: 680/34
F17: 2021 | G17: 700/35
F18: 2022 | G18: 720/36
B19: Kreditt tid (std. 10 dager) | C19: Netto 10 dager | F19: 2023 | G19: 740/37
B20: Kreditt tid (avvikende)
B24: Leveranse betegnelse | E24: Antall | F24: Stk pris | H24: Pris x.mva
B26: Svartjeneste | D26: =Felles!C4 -> August | E26: 1 | F26: 760 | H26: =E26*F26 -> 760
B27: Anrop> 20 | E27: 0 | F27: 38 | H27: =E27*F27 -> 0
B29: 0
B32: Tekst på faktura:
B39: Sum til fakturering kunde eks.mva | H39: =SUM(H26:H38) -> 760

Sheet Fysiodirekte
B3: FAKTURAGRUNNLAG SVARTJENESTE
B5: Kunde | C5: Fysiodirekte | F5: Saksbehandler: | G5: Geir Bodin
B10: Kunde nr | C10: 32126
F11: Dato: | G11: =Felles!C2 -> 46265
B13: Kunden referanse | F13: Ny tabell kunde ok 2017
B14: Navn | C14: Magnhild Faleide Fristad
B15: Bestillingsnr/merknad:
B17: Vår referanse: | C17: Geir Bodin
F18: Fra Mars 2018, veksle mellom 760/20 og tabell
B20: Kreditt tid (std. 10 dager) | C20: Netto 10 dager | F20: Fra 2020, veksle mellom 780/38 og tabell
B21: Kreditt tid (avvikende)
B25: Leveranse betegnelse | E25: Antall | F25: Stk pris | H25: Pris x.mva
B27: Svartjeneste inkl. 20 anrop | D27: =Felles!C4 -> August | E27: 1 | F27: 805 | H27: =E27*F27 -> 805
B28: Svartjeneste | D28: =Felles!C5 -> 0 | E28: 0 | F28: 40 | H28: =E28*F28 -> 0
B33: Tekst på faktura:
B40: Sum til fakturering kunde eks.mva | H40: =SUM(H27:H39) -> 805

Sheet Gass-Pust
B2: FAKTURAGRUNNLAG SVARTJENESTE
B4: Kunde | C4: Gass og Pusteservice AS | F4: Saksbehandler: | G4: Geir
B5: Kunde nr | D5: 31510
F6: Dato: | G6: =Felles!C2 -> 46265
B8: Kunden referanse
B9: Navn | C9: Michael Hansson | F9: Tabell | G9: 0-99
B10: Bestillingsnr/merknad:
F11: Bedriftssvar
B12: Vår referanse: | C12: Geir Bodin
F14: NB bruk epost : faktura@gpsas.no
B15: Kreditt tid (std. 10 dager) | C15: Netto 10 dager
B16: Kreditt tid (avvikende)
B20: Leveranse betegnelse | E20: Antall | F20: Stk pris | H20: Pris x.mva | J20: Pristabell sentralbordet gjeldende fra 01.01.-31.12.2026
B22: Sentralbordtjeneste | D22: =Felles!C4 -> August | E22: 1 | F22: 2960 | H22: =E22*F22 -> 2960 | O22: 2026
B23: Fra oktober 2020 | J23: Vol fra | K23: Vol til | O23: Pris
B24: Utvidet åpningstid | E24: 1 | F24: 360 | H24: =E24*F24 -> 360
J25: 1 | K25: 99 | O25: 2960
B26: Statistikk til: michael@gpsas.no | J26: 100 | K26: 149 | O26: 3580
J27: 150 | K27: 199 | O27: 4090
J28: 200 | K28: 249 | O28: 4670
J29: 250 | K29: 299 | O29: 5760
J30: 300 | K30: 349 | O30: 6830
J31: 350 | K31: 399 | O31: 7920
B32: Tekst på faktura: | J32: 400 | K32: 449 | O32: 8980
J33: 450 | K33: 499 | O33: 10080
J34: 500 | K34: 549 | O34: 11150
J35: 550 | K35: 599 | O35: 12200
J36: 600 | K36: 649 | O36: 13260
J37: 650 | K37: 699 | O37: 14360
J38: 700 | K38: 749 | O38: 15430
B39: Sum til fakturering kunde eks.mva | H39: =SUM(H22:H38) -> 3320 | J39: 750 | K39: 799 | O39: 16530
J40: 800 | K40: 849 | O40: 17590
J41: 850 | K41: 899 | O41: 18680
J42: 900 | K42: 949 | O42: 19750
J43: 950 | K43: 999 | O43: 20820
J44: 1000 | K44: 1099 | O44: 23000
J45: 1100 | K45: 1199 | O45: 24100
J46: 1200 | K46: 1299 | O46: 26260
J47: 1300 | K47: 1399 | O47: 28400
J48: 1400 | K48: 1499 | O48: 30240
...

Sheet Gulvfag
B2: FAKTURAGRUNNLAG SVARTJENESTE
B4: Kunde | C4: Gulvfag Norge AS | F4: Saksbehandler: | G4: Geir
B9: Kunde nr
F10: Dato: | G10: =Felles!C2 -> 46265
B12: Kunden referanse
B13: Navn | C13: Mads Esbersen | G13: Oppstart sep 2016
B14: Bestillingsnr/merknad:
B16: Vår referanse: | C16: Geir Bodin
B19: Kreditt tid (std. 10 dager) | C19: Netto 10 dager | G19: Pris står i 2017/nye priser 2018 | I19: ny pris i 2026
B20: Kreditt tid (avvikende)
G21: =52+93+36+26+8 -> 215
B24: Leveranse betegnelse | E24: Antall | F24: Stk pris | H24: Pris x.mva
B28: Sentralbordtjeneste tabell | E28: 1 | F28: 700 | H28: =SUM(E28*F28) -> 700 | J28: 700 inntil 20 besvarte anrop + 36 pr anrop mer enn 20
B29: Abnm Nye Gulv Norge | E29: 1 | F29: 139 | H29: =E29*F29 -> 139
B30: Abnm Adler Parkettsliperi | E30: 1 | F30: 139 | H30: =E30*F30 -> 139
B31: Abnm Hytteguttene | E31: 1 | F31: 139 | H31: =E31*F31 -> 139
B32: Anrop mellom 21 - 69 | E32: 26 | F32: 36 | H32: =E32*F32 -> 936
H33: =SUM(H28:H32) -> 2053
B38: Tekst på faktura:
B45: Sum til fakturering kunde eks.mva | H45: =SUM(H28:H44) -> 4106
B47: Jan | C47: Feb | D47: mars | E47: april | F47: mai | G47: Juni | H47: Juli | I47: aug | J47: sept | K47: okt | L47: November | M47: Desember
A48: 2025 | B48: =39+0+11+26 -> 76 | C48: =16+15+27+0 -> 58 | E48: =10+0+31+36 -> 77 | F48: =SUM(F49:F51) -> 71 | G48: 29 | H48: 27 | I48: 27 | J48: 13 | K48: 45 | L48: 36
A49: Gulvfag | F49: 25 | G49: 1 | H49: 2 | I49: 3 | J49: 1 | K49: 1 | L49: 0
A50: Nye Gulv Norge | F50: 27 | G50: 28 | H50: 10 | I50: 13 | J50: 18 | K50: 19 | L50: 10
A51: Adler | F51: 19 | G51: 0 | H51: 0 | I51: 0 | J51: 0 | K51: 0 | L51: 0
A52: Hytteguttene | F52: =SUM(F48:F51) -> 142 | G52: =SUM(G48:G51) -> 58 | H52: =SUM(H48:H51) -> 39 | I52: =SUM(I48:I51) -> 43 | J52: =SUM(J48:J51) -> 32 | K52: =SUM(K48:K51) -> 65 | L52: =SUM(L48:L51) -> 46
B53: Jan | C53: Feb | D53: mars | E53: april | F53: mai | G53: juni | H53: juli | I53: aug | J53: sept | K53: okt | L53: nov | M53: des
A54: 2026
A55: Gulvfag | B55: 33 | C55: 25 | D55: 27 | E55: 20 | F55: 19 | G55: 28 | H55: 8 | I55: 22
A56: Nye Gulv Norge | B56: 3 | C56: 2 | D56: 1 | E56: 5 | F56: 1 | G56: 1 | H56: 0 | I56: 0
A57: Adler | B57: 13 | C57: 26 | D57: 18 | E57: 15 | F57: 19 | G57: 17 | H57: 18 | I57: 14
A58: Hytteguttene | B58: 0 | C58: 0 | D58: 0 | E58: 0 | F58: 0 | G58: 0 | H58: 0 | I58: 0
B59: =SUM(B55:B58) -> 49 | C59: =SUM(C55:C58) -> 53 | D59: =SUM(D55:D58) -> 46 | E59: =SUM(E55:E58) -> 40 | F59: =SUM(F55:F58) -> 39 | G59: =SUM(G55:G58) -> 46 | H59: =SUM(H55:H58) -> 26 | I59: 36

Sheet Gunvaldsen
B2: FAKTURAGRUNNLAG SVARTJENESTE
B4: Kunde | C4: Gunvaldsen og sønn | F4: Saksbehandler: | G4: Geir
B9: Kunde nr | C9: 32739
F10: Dato: | G10: =Felles!C2 -> 46265
B12: Kunden referanse
B13: Navn | F13: Etablert: Mrmobile /juli 2017
B14: Bestillingsnr/merknad:
F15: Tabell: | G15: Fast pris inntil 40 anrop + stykkpris per anrop mer enn 40
B16: Vår referanse: | C16: Geir Bodin | F16: Ny pris 2026 | G16: 1180 | H16: Stykkpris | I16: 27
B19: Kreditt tid (std. 10 dager) | C19: Netto 10 dager
B20: Kreditt tid (avvikende)
B24: Leveranse betegnelse | E24: Antall | F24: Stk pris | H24: Pris x.mva
B26: Svartjeneste inkl. 40 anrop | E26: 1 | F26: 1180 | H26: =E26*F26 -> 1180
B27: Anrop > 40 | E27: 17 | F27: 27 | H27: =E27*F27 -> 459
B32: Tekst på faktura:
B39: Sum til fakturering kunde eks.mva | H39: =SUM(H26:H38) -> 1639

Sheet IKT-Nor
B2: FAKTURAGRUNNLAG SVARTJENESTE
B4: Kunde | C4: IKT Nor | F4: Saksbehandler:
B5: Kunde nr | C5: 31643
F6: Dato: | G6: =Felles!C2 -> 46265
B8: Kunden referanse
B9: Navn | C9: Morten Oanes
B10: Bestillingsnr/merknad: | F10: Etablert juli 2013
B12: Vår referanse: | C12: Geir Bodin | E12: 2016 | F12: 620/31
E13: 2017 | F13: 640/32
E14: 2018 | F14: 660/33
B15: Kreditt tid (std. 10 dager) | C15: Netto 10 dager | E15: 2019 | F15: 680/34
B16: Kreditt tid (avvikende) | E16: 2020 | F16: 700/35
E17: 2021 | F17: 720/36
E18: 2022 | F18: 740/37
E19: 2023 | F19: 760/38
E20: 2024 | F20: 780/39
E21: 2025 | F21: 820/40
E22: 2026 | F22: 860/42
B23: Leveranse betegnelse | E23: Antall | F23: Stk pris | H23: Pris x.mva
B25: Svartjeneste inkl. 20 samtaler | D25: =Felles!C4 -> August | E25: 1 | F25: 860 | H25: =E25*F25 -> 860
B26: Anrop > 20 | E26: 0 | F26: 42 | H26: =E26*F26 -> 0
B31: Tekst på faktura:
B38: Sum til fakturering kunde eks.mva | H38: =SUM(H25:H37) -> 860

Sheet Invicta
B2: FAKTURAGRUNNLAG SVARTJENESTE
B4: Kunde | C4: Invicta | F4: Saksbehandler: | G4: Geir
B5: Kunde nr | C5: 32733
F6: Dato: | G6: =Felles!C2 -> 46265
B8: Kunden referanse
B9: Navn | C9: Kevin Hughes
B10: Bestillingsnr/merknad:
F11: Etablert: MrMobile kunde/juli 2017
B12: Vår referanse: | C12: Geir Bodin
F13: Tabell: 1990/100 anrop
F14: Egen avtale > 200 anrop 2460
B15: Kreditt tid (std. 10 dager) | C15: Netto 30 dager | F15: Deretter 15 pr anrop
B16: Kreditt tid (avvikende)
F17: 2022: 2540,- | I17: 2026(konsumpris 1,031
F18: Ny pris 2025 | G18: 2810 | I18: Ny pris 2026 | J18: 2900
B20: Leveranse betegnelse | E20: Antall | F20: Stk pris | H20: Pris x.mva
B22: Sentralbordtjeneste > 200 | D22: =Felles!C4 -> August | E22: 1 | F22: 2900 | H22: =E22*F22 -> 2900
B23: Anrop > 200 | E23: 0 | F23: 18 | H23: =E23*F23 -> 0
B28: Tekst på faktura:
B35: Sum til fakturering kunde eks.mva | H35: =SUM(H22:H34) -> 2900

Sheet JCDec
B2: FAKTURAGRUNNLAG SVARTJENESTE
B4: Kunde | C4: JCDecaux Norge AS | F4: Saksbehandler: | G4: Espen
B5: Kunde nr | C5: 31299
F6: Dato: | G6: =Felles!C2 -> 46265
B8: Kunden referanse
B9: Navn | C9: NY
B10: Bestillingsnr/merknad:
B12: Vår referanse: | C12: Espen Larsen
B15: Kreditt tid (std. 10 dager) | C15: Netto 30 dager
B16: Kreditt tid (avvikende) | F16: Ny pris 2026 juni | G16: Fastpris pr mnd = 2000,- inkl 20 anrop. Kr. Pr anrop over 20 ( juni)
F17: Ny pris 2026 | G17: fra 38 til 40
B20: Leveranse betegnelse | E20: Antall | F20: Stk pris | H20: Pris x.mva
B22: Sentralbordtjeneste | D22: =Felles!C4 -> August | E22: 0
B23: sentralbordtjeneste juni inkl 20 anrop | E23: 1 | F23: 2000 | H23: 2000
B24: Anrop over 20 | E24: 0 | F24: 40 | H24: 0
B28: Tekst på faktura:
B35: Sum til fakturering kunde eks.mva | H35: =SUM(H22:H34) -> 2000

Sheet Kardex
B2: FAKTURAGRUNNLAG SVARTJENESTE
B4: Kunde | C4: Kardex Norge AS | F4: Saksbehandler: | G4: Geir
B5: Kunde nr | C5: 31961 | J5: Pristabell sentralbordet gjeldende fra 01.01.-31.12.2026
F6: Dato: | G6: =Felles!C2 -> 46265
O7: 2026
B8: Kunden referanse | F8: Etablert: 1 mars 2012 | J8: Vol fra | K8: Vol til | O8: Pris
B9: Navn | C9: Anite Heen
B10: Bestillingsnr/merknad: | F10: Tabell | G10: 0-99 | J10: 1 | K10: 99 | O10: 2960
J11: 100 | K11: 149 | O11: 3580
B12: Vår referanse: | C12: Geir Bodin | J12: 150 | K12: 199 | O12: 4090
J13: 200 | K13: 249 | O13: 4670
J14: 250 | K14: 299 | O14: 5760
B15: Kreditt tid (std. 10 dager) | C15: 10 dager | J15: 300 | K15: 349 | O15: 6830
B16: Kreditt tid (avvikende) | C16: _______ dager | J16: 350 | K16: 399 | O16: 7920
J17: 400 | K17: 449 | O17: 8980
J18: 450 | K18: 499 | O18: 10080
J19: 500 | K19: 549 | O19: 11150
B20: Leveranse betegnelse | E20: Antall | F20: Stk pris | H20: Pris x.mva | J20: 550 | K20: 599 | O20: 12200
J21: 600 | K21: 649 | O21: 13260
B22: Svartjeneste | E22: 1 | F22: 2960 | H22: =E22*F22 -> 2960 | J22: 650 | K22: 699 | O22: 14360
J23: 700 | K23: 749 | O23: 15430
J24: 750 | K24: 799 | O24: 16530
J25: 800 | K25: 849 | O25: 17590
J26: 850 | K26: 899 | O26: 18680
J27: 900 | K27: 949 | O27: 19750
J28: 950 | K28: 999 | O28: 20820
J29: 1000 | K29: 1099 | O29: 23000
J30: 1100 | K30: 1199 | O30: 24100
J31: 1200 | K31: 1299 | O31: 26260
J32: 1300 | K32: 1399 | O32: 28400
J33: 1400 | K33: 1499 | O33: 30240
J34: 1500 | K34: 1599 | O34: 32710
... J43: 2400 | K43: 2499 | O43: 52160

Sheet IKM KarstenM
B2: FAKTURAGRUNNLAG SVARTJENESTE
B4: Kunde | C4: IKM Karsten Moholt AS | F4: Saksbehandler: | G4: Geir
B5: Kunde nr | C5: 32792
F6: Dato: | G6: =Felles!C2 -> 46265
G7: Sagt opp i mars. 3 md. Siste faktura juni 2025
B8: Kunden referanse | F8: Etablert: mars 2018
B9: Navn | C9: Beate A.Eide
B10: Bestillingsnr/merknad: | F10: Tabell | G10: 0-99
B12: Vår referanse: | C12: Geir Bodin
B15: Kreditt tid (std. 10 dager) | C15: 30 dager
B16: Kreditt tid (avvikende) | C16: _______ dager
B20: Leveranse betegnelse | E20: Antall | F20: Stk pris | H20: Pris x.mva
B22: Svartjeneste | D22: =Felles!C4 -> August | E22: 0 | F22: 2870 | H22: =E22*F22 -> 0
H24: =SUM(H22:H23) -> 0

Sheet Klinikk ØNH
B2: FAKTURAGRUNNLAG SVARTJENESTE
B4: Kunde | C4: Klinikk Øre Nese Harls | F4: Saksbehandler: | G4: Geir
B5: Kunde nr
F6: Dato: | G6: =Felles!C2 -> 46265 | J6: Volum (antall samtaler) | K6: Pris (NOK)
J7: 0 – 69 | K7: 1500
B8: Kunden referanse | F8: Etablert: | J8: 70 – 89 | K8: 2280
B9: Navn | J9: 90 – 109 | K9: 2870
B10: Bestillingsnr/merknad: | H10: ny tabell fra jan 2026: | J10: 110 – 129 | K10: 3260
J11: 130 – 149 | K11: 3450
B12: Vår referanse: | C12: Geir Bodin | J12: 150 – 169 | K12: 3810
J13: 170 – 189 | K13: 4020
F14: Ny modell fra 18 november 2024 | J14: 190 – 209 | K14: 4260
B15: Kreditt tid (std. 10 dager) | C15: 10 dager | F15: Fast | G15: 399,- år måned | J15: 210 – 229 | K15: 4490
B16: Kreditt tid (avvikende) | C16: _______ dager | F16: Pr besvart anrop | G16: 40,- | J16: 230 – 249 | K16: 4860
F17: Rapport? | J17: 250 – 269 | K17: 5280
J18: 270 – 289 | K18: 5690
J19: 290 – 309 | K19: 6100
B20: Leveranse betegnelse | E20: Antall | F20: Stk pris | H20: Pris x.mva | J20: 310 – 329 | K20: 6520
J21: 330 – 349 | K21: 6940
B22: Svartjeneste | E22: 1 | F22: 6940 | H22: =E22*F22 -> 6940 | J22: 350 – 369 | K22: 7370
J23: 370 – 389 | K23: 7790
J24: 390 – 409 | K24: 8200
J25: 410 – 429 | K25: 8610
J26: 430 – 449 | K26: 9020
B27: Totalt | H27: =SUM(H22:H25) -> 6940 | J27: 450 – 469 | K27: 9440
J28: 470 – 489 | K28: 9860
J29: 490 – 509 | K29: 10280
J30: 510 – 529 | K30: 10700
J31: 530 – 549 | K31: 11120
J32: 550 – 569 | K32: 11530
J33: 570 – 589 | K33: 11940
J34: 590 – 609 | K34: 12350
J35: 610 – 629 | K35: 12760
J36: 630 – 649 | K36: 13180
J37: 650 – 669 | K37: 13610
J38: 670 – 689 | K38: 14030
J39: 690 – 709 | K39: 14450
... J129: 2490 – 2499 | K129: 51540

Sheet Kontroll elektro
B2: FAKTURAGRUNNLAG SVARTJENESTE
B4: Kunde | C4: Kontroll elektro | F4: Saksbehandler: | G4: Geir
B5: Kunde nr | C5: 31272
F6: Dato: | G6: =Felles!C2 -> 46265
B8: Kunden referanse
B9: Navn | C9: Øivind krog Nilsen
B10: Bestillingsnr/merknad: | F10: NB Nofuel
B12: Vår referanse: | C12: Geir Bodin | E12: 2016 | F12: 620/20-31
E13: 2017 | F13: 640/20-32
E14: 2018 | F14: 660/20-33
B15: Kreditt tid (std. 10 dager) | C15: Netto 10 dager | E15: 2019 | F15: 680/20-34
B16: Kreditt tid (avvikende) | E16: 2020 | F16: 700/20-35
E17: 2021 | F17: 720/20-36
E18: 2022 | F18: 740/20-37
E19: 2023 | F19: 760/20-38
E20: 2024 | F20: 780/20-39
E21: 2025 | F21: 820/20-40
E22: 2026 | F22: 860/20-42
B23: Leveranse betegnelse | E23: Antall | F23: Stk pris | H23: Pris x.mva
B25: Sentralbordtjeneste inkl. 20 anrop | E25: 1 | F25: 860 | H25: =E25*F25 -> 860
B26: anrop > 20 | E26: 6 | F26: 42 | H26: =E26*F26 -> 252
B28: Statistikk til: : regnskap@kontrollelektro.no
B31: Tekst på faktura:
B38: Sum til fakturering kunde eks.mva | H38: =SUM(H25:H37) -> 1112

Sheet KTV
B2: FAKTURAGRUNNLAG SVARTJENESTE
B4: Kunde | C4: KTV Group AS | F4: Saksbehandler: | G4: Geir
B5: Kunde nr
F6: Dato: | G6: =Felles!C2 -> 46265
B8: Kunden referanse | F8: Etablert: juni 2014
B9: Navn | C9: Kennet Nilsen
B10: Bestillingsnr/merknad: | F10: Tabell kunde 0-99
B12: Vår referanse: | C12: Geir Bodin | F12: NB! Alle salgstelefoner skal trekkes fra
F14: NB! Bestillingnummer: 35 - egen opplasting faktura
B15: Kreditt tid (std. 10 dager) | C15: Netto 10 dager
B16: Kreditt tid (avvikende) | F16: 10% rabatt fra 1 juli 2017
O19: 2026
B20: Leveranse betegnelse | E20: Antall | F20: Stk pris | H20: Pris x.mva | J20: Vol fra | K20: Vol til | O20: Pris
B22: Sentralbordtjeneste | E22: 1 | F22: 2960 | G22: 0.1 | H22: =F22*(1-G22) -> 2664 | J22: 1 | K22: 99 | O22: 2960
B23: Antall salgstelefoner: | J23: 100 | K23: 149 | O23: 3580
J24: 150 | K24: 199 | O24: 4090
C25: 34 | J25: 200 | K25: 249 | O25: 4670
J26: 250 | K26: 299 | O26: 5760
J27: 300 | K27: 349 | O27: 6830
B28: Tekst på faktura: | J28: 350 | K28: 399 | O28: 7920
J29: 400 | K29: 449 | O29: 8980
J30: 450 | K30: 499 | O30: 10080
J31: 500 | K31: 549 | O31: 11150
J32: 550 | K32: 599 | O32: 12200
J33: 600 | K33: 649 | O33: 13260
J34: 650 | K34: 699 | O34: 14360
B35: Sum til fakturering kunde eks.mva | H35: =SUM(H22:H34) -> 2664 | J35: 700 | K35: 749 | O35: 15430
J36: 750 | K36: 799 | O36: 16530
J37: 800 | K37: 849 | O37: 17590
J38: 850 | K38: 899 | O38: 18680
J39: 900 | K39: 949 | O39: 19750
J40: 950 | K40: 999 | O40: 20820
J41: 1000 | K41: 1099 | O41: 23000
J42: 1100 | K42: 1199 | O42: 24100
J43: 1200 | K43: 1299 | O43: 26260
J44: 1300 | K44: 1399 | O44: 28400
J45: 1400 | K45: 1499 | O45: 30240
J46: 1500 | K46: 1599 | O46: 32710
J47: 1600 | K47: 1699 | O47: 34890
... J55: 2400 | K55: 2499 | O55: 52160

Sheet Nemus Vestfold
C2: FAKTURAGRUNNLAG SVARTJENESTE
C4: Kunde | D4: NEMUS | G4: Saksbehandler:
C5: Kundenr
C6: 33185 | D6: Horten
C7: 33188 | D7: Nætterøy
C8: 33189 | D8: Tønsberg
C9: 33190 | D9: Sandefjord
C10: 33191 | D10: Larvik | G10: Dato: | H10: 45962
C12: Kunden referanse | G12: Etablert | H12: 45962
C13: Navn | D13: Otto Torvik
C14: Bestillingsnr/merknad: | H14: Pristabell
C16: Vår referanse: | D16: Geir Bodin | H16: otto.torvik@nemus.no
C19: Kreditt tid (std. 10 dager) | D19: Netto 10 dager | G19: 0-99
C20: Kreditt tid (avvikende)
G21: Tabell 2025 og 2026
G22: Pris pr besvart samtale mer enn 649 er kr 24,-
C27: Leveranse betegnelse | F27: Antall | G27: Stk pris | I27: Pris x.mva
C29: Svartjeneste inkl 69 samtaler
C30: Horten | F30: Svartjeneste inkl rapport | G30: 1 | I30: 199
C31: Horten | F31: 1 | G31: 3260 | I31: 3260
C32: Nøtterøy | F32: Svartjeneste inkl rapport | G32: 1 | I32: 199
C33: Nøtterøy | F33: 1 | G33: 2280 | I33: 2280
C34: Tønsberg | F34: Svartjeneste inkl rapport | G34: 1 | I34: 199
C35: Tønsberg | F35: 1 | G35: 2280 | I35: 2280
C36: Sandefjord | F36: Svartjeneste inkl rapport | G36: 1 | I36: 199
C37: Sandefjord | F37: 1 | G37: 2280 | I37: 2280
C38: Larvik | F38: Svartjeneste inkl rapport | G38: 1 | I38: 199
C39: Larvik | F39: 1 | G39: 1500 | I39: 1500
F41: Totalt | I41: =SUM(I30:I40) -> 12595
C43: Pristabell_
D44: samtaler | E44: pris
D45: 50-69 | E45: 1500
D46: 70-89 | E46: 2280
D47: 90-109 | E47: 2870
D48: 110-129 | E48: 3260
D49: 130-149 | E49: 3450
D50: 150-169 | E50: 3810
D51: 170-189 | E51: 4020
D52: 190-209 | E52: 4260
D53: 210-229 | E53: 4490
...

Sheet Noah
B2: FAKTURAGRUNNLAG SVARTJENESTE
B4: Kunde | C4: NOAH | F4: Saksbehandler: | G4: Geir Bodin
B9: Kunde nr | C9: ny
F10: Dato: | G10: =Felles!C2 -> 46265
B12: Kunden referanse
B13: Navn | C13: Liv Almenningen | F13: Oppstart: | G13: 42522
B14: Bestillingsnr/merknad: | C14: innkjøpsordre 336
F15: Tabell | G15: 0-99
B16: Vår referanse: | C16: Geir Bodin
F17: Fakturer Epost
B19: Kreditt tid (std. 10 dager) | C19: Netto 10 dager
B20: Kreditt tid (avvikende)
O23: 2026
B24: Leveranse betegnelse | E24: Antall | F24: Stk pris | H24: Pris x.mva | J24: Vol fra | K24: Vol til | O24: Pris
B26: Svartjeneste | E26: 1 | F26: 2960 | H26: =E26*F26 -> 2960 | J26: 1 | K26: 99 | O26: 2960
J27: 100 | K27: 149 | O27: 3580
J28: 150 | K28: 199 | O28: 4090
B29: Statistikk til: lno@noah.no | J29: 200 | K29: 249 | O29: 4670
J30: 250 | K30: 299 | O30: 5760
J31: 300 | K31: 349 | O31: 6830
J32: 350 | K32: 399 | O32: 7920
B33: Tekst på faktura: | J33: 400 | K33: 449 | O33: 8980
J34: 450 | K34: 499 | O34: 10080
J35: 500 | K35: 549 | O35: 11150
J36: 550 | K36: 599 | O36: 12200
J37: 600 | K37: 649 | O37: 13260
J38: 650 | K38: 699 | O38: 14360
J39: 700 | K39: 749 | O39: 15430
B40: Sum til fakturering kunde eks.mva | H40: =SUM(H26:H39) -> 2960 | J40: 750 | K40: 799 | O40: 16530
J41: 800 | K41: 849 | O41: 17590
J42: 850 | K42: 899 | O42: 18680
J43: 900 | K43: 949 | O43: 19750
J44: 950 | K44: 999 | O44: 20820
J45: 1000 | K45: 1099 | O45: 23000
J46: 1100 | K46: 1199 | O46: 24100
J47: 1200 | K47: 1299 | O47: 26260
J48: 1300 | K48: 1399 | O48: 28400
J49: 1400 | K49: 1499 | O49: 30240
J50: 1500 | K50: 1599 | O50: 32710
J51: 1600 | K51: 1699 | O51: 34890
...

Sheet Norenco
B2: FAKTURAGRUNNLAG SVARTJENESTE
B4: Kunde | C4: Norenco Norge AS | F4: Saksbehandler:
C5: Tegleverksveien 99
C6: 3057 Solbergelva
B9: Kunde nr | C9: ny
F10: Dato: | G10: =Felles!C2 -> 46265
B12: Kunden referanse | G12: Bedriftssvar
B13: Navn
B14: Bestillingsnr/merknad: | C14: Arne Haukland | S14: 2026
